Workbook

Sheet Resumen
A1: Backlog de contenidos – Blog Continental Media
A2: Versión 2 (calendario asignado). Fecha: 19/10/2026. Lote inicial de 8 artículos el 19/10/2026; el resto martes y jueves. Siguiente fase: validar keywords, volumen y dificultad.
E3: Calendario de publicación | F3: Valor
A4: Indicador | B4: Valor | C4: Nota | E4: Primera publicación (lote inicial) | F4: =MIN(Backlog!X2:X101) -> 46314
A5: Total de temas | B5: =COUNTA(Backlog!A2:A101) -> 100 | C5: Meta: al menos 100 | E5: Artículos en el lote inicial | F5: =COUNTIF(Backlog!X2:X101,F4) -> 8
A6: Artículos editoriales | B6: =COUNTIF(Backlog!B2:B101,"Editorial") -> 50 | C6: Meta: 50 | E6: Primera publicación del calendario regular | F6: =MIN(Backlog!X2:X101)+1 -> 46315
A7: Guías prácticas (con PDF) | B7: =COUNTIF(Backlog!B2:B101,"Guía práctica") -> 50 | C7: Meta: 50 | E7: Última publicación | F7: =MAX(Backlog!X2:X101) -> 46632
A8: Guías con entregable PDF definido | B8: =COUNTIFS(Backlog!B2:B101,"Guía práctica",Backlog!O2:O101,"?*",Backlog!O2:O101,"<>—") -> 50 | C8: Debe ser igual al número de guías | E8: Semanas de publicación | F8: =MAX(Backlog!Z2:Z101) -> 46
A9: Temas que re-redactan contenido existente | B9: =COUNTIF(Backlog!K2:K101,"Re-redacción 2026") -> 72 | C9: Tienen un artículo base en el blog actual | E9: Artículos fuera de martes/jueves (lote inicial excluido) | F9: =COUNTIFS(Backlog!AA2:AA101,"Calendario semanal",Backlog!Y2:Y101,"<>martes",Backlog!Y2:Y101,"<>jueves") -> 0
A10: Temas nuevos | B10: =COUNTIF(Backlog!K2:K101,"Nuevo") -> 28
A11: Prioridad alta | B11: =COUNTIF(Backlog!R2:R101,"Alta") -> 32
A12: Prioridad media | B12: =COUNTIF(Backlog!R2:R101,"Media") -> 52
A13: Prioridad baja | B13: =COUNTIF(Backlog!R2:R101,"Baja") -> 16
A14: Posts actuales analizados | B14: =COUNTA('Posts actuales'!A2:A1000) -> 188 | C14: Hoja "Posts actuales" (incluye el índice /blog/)
A16: Destino de los posts actuales
A17: Decisión | B17: Posts | C17: Qué significa
A18: Re-redactar v2026 | B18: =COUNTIF('Posts actuales'!D2:D1000,A18) -> 69 | C18: Reescribir con enfoque 2026 en el nuevo blog
A19: Actualizar v2026 | B19: =COUNTIF('Posts actuales'!D2:D1000,A19) -> 3 | C19: Posts de 2025 que solo necesitan actualización
A20: Consolidar | B20: =COUNTIF('Posts actuales'!D2:D1000,A20) -> 83 | C20: Se fusionan en otro artículo; la URL se redirige con 301
A21: Mantener (vigente) | B21: =COUNTIF('Posts actuales'!D2:D1000,A21) -> 3 | C21: Posts de 2026; se conservan y se enlazan con el tema relacionado
A22: Descartar | B22: =COUNTIF('Posts actuales'!D2:D1000,A22) -> 29 | C22: Sin valor SEO actual; 410 o 301 a categoría
A23: Reemplazar | B23: =COUNTIF('Posts actuales'!D2:D1000,A23) -> 1 | C23: Índice del blog
A24: Total | B24: =SUM(B18:B23) -> 188
A26: Calendario de publicación (lote inicial + martes y jueves)
A27: Mes | B27: Editoriales | C27: Guías prácticas
A28: Oct 2026 | B28: =COUNTIFS(Backlog!$T$2:$T$101,A28,Backlog!$B$2:$B$101,"Editorial") -> 6 | C28: =COUNTIFS(Backlog!$T$2:$T$101,A28,Backlog!$B$2:$B$101,"Guía práctica") -> 6
A29: Nov 2026 | B29: =COUNTIFS(Backlog!$T$2:$T$101,A29,Backlog!$B$2:$B$101,"Editorial") -> 4 | C29: =COUNTIFS(Backlog!$T$2:$T$101,A29,Backlog!$B$2:$B$101,"Guía práctica") -> 4
A30: Dic 2026 | B30: =COUNTIFS(Backlog!$T$2:$T$101,A30,Backlog!$B$2:$B$101,"Editorial") -> 5 | C30: =COUNTIFS(Backlog!$T$2:$T$101,A30,Backlog!$B$2:$B$101,"Guía práctica") -> 5
A31: Ene 2027 | B31: =COUNTIFS(Backlog!$T$2:$T$101,A31,Backlog!$B$2:$B$101,"Editorial") -> 4 | C31: =COUNTIFS(Backlog!$T$2:$T$101,A31,Backlog!$B$2:$B$101,"Guía práctica") -> 4
A32: Feb 2027 | B32: =COUNTIFS(Backlog!$T$2:$T$101,A32,Backlog!$B$2:$B$101,"Editorial") -> 4 | C32: =COUNTIFS(Backlog!$T$2:$T$101,A32,Backlog!$B$2:$B$101,"Guía práctica") -> 4
A33: Mar 2027 | B33: =COUNTIFS(Backlog!$T$2:$T$101,A33,Backlog!$B$2:$B$101,"Editorial") -> 5 | C33: =COUNTIFS(Backlog!$T$2:$T$101,A33,Backlog!$B$2:$B$101,"Guía práctica") -> 4
A34: Abr 2027 | B34: =COUNTIFS(Backlog!$T$2:$T$101,A34,Backlog!$B$2:$B$101,"Editorial") -> 4 | C34: =COUNTIFS(Backlog!$T$2:$T$101,A34,Backlog!$B$2:$B$101,"Guía práctica") -> 5
A35: May 2027 | B35: =COUNTIFS(Backlog!$T$2:$T$101,A35,Backlog!$B$2:$B$101,"Editorial") -> 4 | C35: =COUNTIFS(Backlog!$T$2:$T$101,A35,Backlog!$B$2:$B$101,"Guía práctica") -> 4
A36: Jun 2027 | B36: =COUNTIFS(Backlog!$T$2:$T$101,A36,Backlog!$B$2:$B$101,"Editorial") -> 5 | C36: =COUNTIFS(Backlog!$T$2:$T$101,A36,Backlog!$B$2:$B$101,"Guía práctica") -> 4
A37: Jul 2027 | B37: =COUNTIFS(Backlog!$T$2:$T$101,A37,Backlog!$B$2:$B$101,"Editorial") -> 4 | C37: =COUNTIFS(Backlog!$T$2:$T$101,A37,Backlog!$B$2:$B$101,"Guía práctica") -> 5
A38: Ago 2027 | B38: =COUNTIFS(Backlog!$T$2:$T$101,A38,Backlog!$B$2:$B$101,"Editorial") -> 5 | C38: =COUNTIFS(Backlog!$T$2:$T$101,A38,Backlog!$B$2:$B$101,"Guía práctica") -> 4
A39: Sep 2027 | B39: =COUNTIFS(Backlog!$T$2:$T$101,A39,Backlog!$B$2:$B$101,"Editorial") -> 0 | C39: =COUNTIFS(Backlog!$T$2:$T$101,A39,Backlog!$B$2:$B$101,"Guía práctica") -> 1
A40: Total | B40: =SUM(B28:B39) -> 50 | C40: =SUM(C28:C39) -> 50
A41: Supuestos y notas
A42: • La sección de servicios del sitio temporal (labs-publifix.github.io/continental-media) aún no tiene contenido; los 9 pilares son provisionales y deben confirmarse con la lista oficial de servicios.
...

Sheet Backlog
A1: ID | B1: Tipo | C1: Título tentativo | D1: Pilar | E1: Keyword semilla (por validar) | F1: Intención de búsqueda | G1: Etapa del embudo | H1: Objetivo SEO | I1: Audiencia / sector | J1: Mercado | K1: Origen | L1: Artículo base a re-redactar (URL actual) | M1: Otros posts a consolidar (301) | N1: Qué actualizar / ángulo 2026 | O1: Entregable PDF (solo guías) | P1: Servicio a impulsar | Q1: Cruces (IDs) | R1: Prioridad | S1: Orden sugerido | T1: Mes de publicación | U1: Volumen de búsqueda | V1: Dificultad SEO | W1: Estado | X1: Fecha de publicación | Y1: Día | Z1: Semana | AA1: Lote
A2: E-01 | B2: Editorial | C2: IA en el marketing 2026: lo que cambió y lo que sigue siendo humano | D2: IA aplicada al marketing | E2: inteligencia artificial en el marketing | F2: Informacional | G2: TOFU | H2: Captar tráfico informacional en «inteligencia artificial en el marketing» y construir autoridad temática en ia aplicada al marketing. | I2: General | J2: México + EE.UU. | K2: Re-redacción 2026 | L2: https://www.continentalmedia.com.mx/2023/11/el-impacto-de-la-inteligencia-artificial-en-el-marketing/ | N2: Actualizar con casos 2026; postura "la IA multiplica a tu equipo" | O2: — | P2: IA aplicada a marketing y comunicación | Q2: E-02; E-07; E-09; G-18; G-19; G-22 | R2: Alta | S2: 3 | T2: =CHOOSE(MONTH(X2),"Ene","Feb","Mar","Abr","May","Jun","Jul","Ago","Sep","Oct","Nov","Dic")&" "&YEAR(X2) -> Oct 2026 | W2: Idea | X2: 46314 | Y2: =CHOOSE(WEEKDAY(X2,2),"lunes","martes","miércoles","jueves","viernes","sábado","domingo") -> lunes | Z2: =INT((X2-MIN($X$2:$X$101))/7)+1 -> 1 | AA2: =IF(X2=MIN($X$2:$X$101),"Lanzamiento","Calendario semanal") -> Lanzamiento
A3: E-02 | B3: Editorial | C3: La IA no reemplaza a tu equipo, lo multiplica: cómo trabaja una agencia en 2026 | D3: IA aplicada al marketing | E3: agencia de marketing con inteligencia artificial | F3: Informacional | G3: TOFU | H3: Captar tráfico informacional en «agencia de marketing con inteligencia artificial» y construir autoridad temática en ia aplicada al marketing. | I3: General | J3: México + EE.UU. | K3: Nuevo | N3: Artículo bandera alineado al mensaje del hero del sitio nuevo | O3: — | P3: IA aplicada a marketing y comunicación | Q3: E-01; E-04; G-21; G-23 | R3: Media | S3: 21 | T3: =CHOOSE(MONTH(X3),"Ene","Feb","Mar","Abr","May","Jun","Jul","Ago","Sep","Oct","Nov","Dic")&" "&YEAR(X3) -> Dic 2026 | W3: Idea | X3: 46357 | Y3: =CHOOSE(WEEKDAY(X3,2),"lunes","martes","miércoles","jueves","viernes","sábado","domingo") -> martes | Z3: =INT((X3-MIN($X$2:$X$101))/7)+1 -> 7 | AA3: =IF(X3=MIN($X$2:$X$101),"Lanzamiento","Calendario semanal") -> Calendario semanal
A4: E-03 | B4: Editorial | C4: SEO en la era de la búsqueda con IA: AI Overviews, GEO y qué hacer con tu marca | D4: IA aplicada al marketing | E4: SEO e inteligencia artificial | F4: Informacional | G4: TOFU | H4: Captar tráfico informacional en «SEO e inteligencia artificial» y construir autoridad temática en ia aplicada al marketing. | I4: General | J4: México + EE.UU. | K4: Nuevo | N4: Explicar GEO/AEO y cómo cambian clics y visibilidad | O4: — | P4: IA aplicada a marketing y comunicación | Q4: E-05; E-11; G-24; G-35; G-36 | R4: Alta | S4: 5 | T4: =CHOOSE(MONTH(X4),"Ene","Feb","Mar","Abr","May","Jun","Jul","Ago","Sep","Oct","Nov","Dic")&" "&YEAR(X4) -> Oct 2026 | W4: Idea | X4: 46314 | Y4: =CHOOSE(WEEKDAY(X4,2),"lunes","martes","miércoles","jueves","viernes","sábado","domingo") -> lunes | Z4: =INT((X4-MIN($X$2:$X$101))/7)+1 -> 1 | AA4: =IF(X4=MIN($X$2:$X$101),"Lanzamiento","Calendario semanal") -> Lanzamiento
A5: E-04 | B5: Editorial | C5: Agentes de IA en WhatsApp: promesas, límites y casos reales para empresas | D5: IA aplicada al marketing | E5: chatbot de WhatsApp con IA | F5: Informacional | G5: MOFU | H5: Capturar búsquedas de evaluación en «chatbot de WhatsApp con IA» y canalizarlas hacia ia aplicada a marketing y comunicación. | I5: General | J5: México + EE.UU. | K5: Re-redacción 2026 | L5: https://www.continentalmedia.com.mx/2022/06/chatbots-de-whatsapp-que-son-y-como-utilizarlos/ | N5: Pasar de chatbots de reglas a agentes con IA; riesgos y buenas prácticas | O5: — | P5: IA aplicada a marketing y comunicación | Q5: E-02; G-20; G-21 | R5: Alta | S5: 7 | T5: =CHOOSE(MONTH(X5),"Ene","Feb","Mar","Abr","May","Jun","Jul","Ago","Sep","Oct","Nov","Dic")&" "&YEAR(X5) -> Oct 2026 | W5: Idea | X5: 46314 | Y5: =CHOOSE(WEEKDAY(X5,2),"lunes","martes","miércoles","jueves","viernes","sábado","domingo") -> lunes | Z5: =INT((X5-MIN($X$2:$X$101))/7)+1 -> 1 | AA5: =IF(X5=MIN($X$2:$X$101),"Lanzamiento","Calendario semanal") -> Lanzamiento
A6: E-05 | B6: Editorial | C6: Contenido con IA sin sonar genérico: cómo conservar la voz de tu marca | D6: IA aplicada al marketing | E6: contenido generado con IA | F6: Informacional | G6: TOFU | H6: Captar tráfico informacional en «contenido generado con IA» y construir autoridad temática en ia aplicada al marketing. | I6: General | J6: México + EE.UU. | K6: Nuevo | N6: Criterios editoriales, revisión humana y señales de calidad | O6: — | P6: IA aplicada a marketing y comunicación | Q6: E-03; E-06; E-33; E-43; G-19; G-30 | R6: Alta | S6: 9 | T6: =CHOOSE(MONTH(X6),"Ene","Feb","Mar","Abr","May","Jun","Jul","Ago","Sep","Oct","Nov","Dic")&" "&YEAR(X6) -> Oct 2026 | W6: Idea | X6: 46315 | Y6: =CHOOSE(WEEKDAY(X6,2),"lunes","martes","miércoles","jueves","viernes","sábado","domingo") -> martes | Z6: =INT((X6-MIN($X$2:$X$101))/7)+1 -> 1 | AA6: =IF(X6=MIN($X$2:$X$101),"Lanzamiento","Calendario semanal") -> Calendario semanal
A7: E-06 | B7: Editorial | C7: Ética y transparencia con IA en comunicación: cuándo avisar que usaste IA | D7: IA aplicada al marketing | E7: ética de la IA en marketing | F7: Informacional | G7: TOFU | H7: Captar tráfico informacional en «ética de la IA en marketing» y construir autoridad temática en ia aplicada al marketing. | I7: General | J7: México + EE.UU. | K7: Nuevo | N7: Tendencias de regulación y confianza del consumidor | O7: — | P7: IA aplicada a marketing y comunicación | Q7: E-05; E-34; G-25 | R7: Media | S7: 23 | T7: =CHOOSE(MONTH(X7),"Ene","Feb","Mar","Abr","May","Jun","Jul","Ago","Sep","Oct","Nov","Dic")&" "&YEAR(X7) -> Dic 2026 | W7: Idea | X7: 46364 | Y7: =CHOOSE(WEEKDAY(X7,2),"lunes","martes","miércoles","jueves","viernes","sábado","domingo") -> martes | Z7: =INT((X7-MIN($X$2:$X$101))/7)+1 -> 8 | AA7: =IF(X7=MIN($X$2:$X$101),"Lanzamiento","Calendario semanal") -> Calendario semanal
A8: E-07 | B8: Editorial | C8: De ChatGPT a los asistentes de IA: cómo evolucionó el marketing asistido | D8: IA aplicada al marketing | E8: ChatGPT para marketing | F8: Informacional | G8: TOFU | H8: Captar tráfico informacional en «ChatGPT para marketing» y construir autoridad temática en ia aplicada al marketing. | I8: General | J8: México + EE.UU. | K8: Re-redacción 2026 | L8: https://www.continentalmedia.com.mx/2023/02/chatgpt-que-es-y-como-puede-ayudarte-a-crear-campanas-de-marketing/ | N8: Línea de tiempo 2023→2026 y qué sobrevivió a la moda | O8: — | P8: IA aplicada a marketing y comunicación | Q8: E-01; G-18; G-22 | R8: Media | S8: 25 | T8: =CHOOSE(MONTH(X8),"Ene","Feb","Mar","Abr","May","Jun","Jul","Ago","Sep","Oct","Nov","Dic")&" "&YEAR(X8) -> Dic 2026 | W8: Idea | X8: 46371 | Y8: =CHOOSE(WEEKDAY(X8,2),"lunes","martes","miércoles","jueves","viernes","sábado","domingo") -> martes | Z8: =INT((X8-MIN($X$2:$X$101))/7)+1 -> 9 | AA8: =IF(X8=MIN($X$2:$X$101),"Lanzamiento","Calendario semanal") -> Calendario semanal
A9: E-08 | B9: Editorial | C9: Metaverso, realidad aumentada y gaming: qué quedó de la promesa para las marcas | D9: IA aplicada al marketing | E9: metaverso para marcas | F9: Informacional | G9: TOFU | H9: Captar tráfico informacional en «metaverso para marcas» y construir autoridad temática en ia aplicada al marketing. | I9: General | J9: México + EE.UU. | K9: Re-redacción 2026 | L9: https://www.continentalmedia.com.mx/2022/05/que-es-el-metaverso-y-cuales-seran-sus-beneficios/ | M9: https://www.continentalmedia.com.mx/2013/11/realidad-aumentada-o-ciencia-ficcion/ https://www.continentalmedia.com.mx/2013/08/videojuegos-un-medio-mas-para-la-publicidad/ | N9: Balance honesto; rescatar AR y publicidad en videojuegos | O9: — | P9: IA aplicada a marketing y comunicación | Q9: E-11; E-39; E-43 | R9: Baja | S9: 79 | T9: =CHOOSE(MONTH(X9),"Ene","Feb","Mar","Abr","May","Jun","Jul","Ago","Sep","Oct","Nov","Dic")&" "&YEAR(X9) -> Jun 2027 | W9: Idea | X9: 46560 | Y9: =CHOOSE(WEEKDAY(X9,2),"lunes","martes","miércoles","jueves","viernes","sábado","domingo") -> martes | Z9: =INT((X9-MIN($X$2:$X$101))/7)+1 -> 36 | AA9: =IF(X9=MIN($X$2:$X$101),"Lanzamiento","Calendario semanal") -> Calendario semanal
A10: E-09 | B10: Editorial | C10: Tendencias de marketing 2027: lo que las marcas deben preparar desde hoy | D10: Estrategia de marketing y contenidos | E10: tendencias de marketing 2027 | F10: Informacional | G10: TOFU | H10: Captar tráfico informacional en «tendencias de marketing 2027» y construir autoridad temática en estrategia de marketing y contenidos. | I10: General | J10: México + EE.UU. | K10: Re-redacción 2026 | L10: https://www.continentalmedia.com.mx/2023/12/5-tendencias-de-marketing-para-2024/ | M10: https://www.continentalmedia.com.mx/2023/01/8-tendencias-de-marketing-para-este-2023/ https://www.continentalmedia.com.mx/2013/12/cuales-seran-las-tendencias-de-marketing-2014/ https://www.continentalmedia.com.mx/2013/01/la-forma-de-hacer-marketing-en-el-2013/ | N10: Publicar en nov-2026; mantener URL evergreen y actualizar cada año | O10: — | P10: Estrategia de marketing 360 | Q10: E-01; G-01; G-07 | R10: Alta | S10: 1 | T10: =CHOOSE(MONTH(X10),"Ene","Feb","Mar","Abr","May","Jun","Jul","Ago","Sep","Oct","Nov","Dic")&" "&YEAR(X10) -> Oct 2026 | W10: Idea | X10: 46314 | Y10: =CHOOSE(WEEKDAY(X10,2),"lunes","martes","miércoles","jueves","viernes","sábado","domingo") -> lunes | Z10: =INT((X10-MIN($X$2:$X$101))/7)+1 -> 1 | AA10: =IF(X10=MIN($X$2:$X$101),"Lanzamiento","Calendario semanal") -> Lanzamiento
A11: E-10 | B11: Editorial | C11: Alcance orgánico en redes sociales: ¿sigue valiendo la pena para tu empresa? | D11: Redes sociales y comunidad | E11: alcance orgánico en redes sociales | F11: Informacional | G11: TOFU | H11: Captar tráfico informacional en «alcance orgánico en redes sociales» y construir autoridad temática en redes sociales y comunidad. | I11: General | J11: México + EE.UU. | K11: Re-redacción 2026 | L11: https://www.continentalmedia.com.mx/2014/06/empresa-lista-redes-sociales/ | M11: https://www.continentalmedia.com.mx/2012/12/6-razones-pymes-usar-redes-sociales/ https://www.continentalmedia.com.mx/2012/12/redes-sociales-en-pymes/ https://www.continentalmedia.com.mx/2013/04/la-evolucion-de-las-redes-sociales/ | N11: Datos 2026 sobre alcance orgánico vs. pauta; cuándo conviene cada uno | O11: — | P11: Gestión de redes sociales y community management | Q11: E-11; G-09; G-17 | R11: Media | S11: 27 | T11: =CHOOSE(MONTH(X11),"Ene","Feb","Mar","Abr","May","Jun","Jul","Ago","Sep","Oct","Nov","Dic")&" "&YEAR(X11) -> Dic 2026 | W11: Idea | X11: 46378 | Y11: =CHOOSE(WEEKDAY(X11,2),"lunes","martes","miércoles","jueves","viernes","sábado","domingo") -> martes | Z11: =INT((X11-MIN($X$2:$X$101))/7)+1 -> 10 | AA11: =IF(X11=MIN($X$2:$X$101),"Lanzamiento","Calendario semanal") -> Calendario semanal
A12: E-11 | B12: Editorial | C12: Social search: por qué TikTok e Instagram ya son buscadores y cómo aparecer | D12: Redes sociales y comunidad | E12: TikTok como buscador | F12: Informacional | G12: TOFU | H12: Captar tráfico informacional en «TikTok como buscador» y construir autoridad temática en redes sociales y comunidad. | I12: General | J12: México + EE.UU. | K12: Re-redacción 2026 | L12: https://www.continentalmedia.com.mx/2022/10/tiktok-now-que-es-y-por-que-lo-comparan-con-be-real/ | M12: https://www.continentalmedia.com.mx/2013/10/google-la-red-social/ | N12: SEO social: palabras clave en captions, subtítulos y perfil | O12: — | P12: Gestión de redes sociales y community management | Q12: E-03; E-08; E-10; E-14; G-10; G-11 | R12: Media | S12: 29 | T12: =CHOOSE(MONTH(X12),"Ene","Feb","Mar","Abr","May","Jun","Jul","Ago","Sep","Oct","Nov","Dic")&" "&YEAR(X12) -> Dic 2026 | W12: Idea | X12: 46385 | Y12: =CHOOSE(WEEKDAY(X12,2),"lunes","martes","miércoles","jueves","viernes","sábado","domingo") -> martes | Z12: =INT((X12-MIN($X$2:$X$101))/7)+1 -> 11 | AA12: =IF(X12=MIN($X$2:$X$101),"Lanzamiento","Calendario semanal") -> Calendario semanal
A13: E-12 | B13: Editorial | C13: Humanizar tu marca: por qué la autenticidad le gana al contenido perfecto | D13: Redes sociales y comunidad | E13: humanizar la marca | F13: Informacional | G13: TOFU | H13: Captar tráfico informacional en «humanizar la marca» y construir autoridad temática en redes sociales y comunidad. | I13: General | J13: México + EE.UU. | K13: Re-redacción 2026 | L13: https://www.continentalmedia.com.mx/2021/11/la-importancia-de-humanizar-tu-marca-inbound-marketing/ | M13: https://www.continentalmedia.com.mx/2014/03/las-5-mejores-marcas-en-redes-sociales-en-mexico/ | N13: Ejemplos de marcas mexicanas; cómo producirlo sin improvisar | O13: — | P13: Gestión de redes sociales y community management | Q13: E-13; E-15; E-19; E-26; E-49; G-09; G-30 | R13: Alta | S13: 11 | T13: =CHOOSE(MONTH(X13),"Ene","Feb","Mar","Abr","May","Jun","Jul","Ago","Sep","Oct","Nov","Dic")&" "&YEAR(X13) -> Oct 2026 | W13: Idea | X13: 46322 | Y13: =CHOOSE(WEEKDAY(X13,2),"lunes","martes","miércoles","jueves","viernes","sábado","domingo") -> martes | Z13: =INT((X13-MIN($X$2:$X$101))/7)+1 -> 2 | AA13: =IF(X13=MIN($X$2:$X$101),"Lanzamiento","Calendario semanal") -> Calendario semanal
A14: E-13 | B14: Editorial | C14: Marketing de influencia en 2026: micro-influencers, creadores y contenido UGC | D14: Redes sociales y comunidad | E14: marketing de influencia | F14: Informacional | G14: TOFU | H14: Captar tráfico informacional en «marketing de influencia» y construir autoridad temática en redes sociales y comunidad. | I14: General | J14: México + EE.UU. | K14: Re-redacción 2026 | L14: https://www.continentalmedia.com.mx/2014/03/que-es-el-marketing-de-influencia/ | M14: https://www.continentalmedia.com.mx/2014/01/celebridades-y-marcas-se-llevan-bien/ https://www.continentalmedia.com.mx/2014/01/celebridades-marcas-y-escandalos/ | N14: Modelos de colaboración, métricas y riesgos de reputación | O14: — | P14: Gestión de redes sociales y community management | Q14: E-12; E-15; G-16 | R14: Media | S14: 31 | T14: =CHOOSE(MONTH(X14),"Ene","Feb","Mar","Abr","May","Jun","Jul","Ago","Sep","Oct","Nov","Dic")&" "&YEAR(X14) -> Ene 2027 | W14: Idea | X14: 46392 | Y14: =CHOOSE(WEEKDAY(X14,2),"lunes","martes","miércoles","jueves","viernes","sábado","domingo") -> martes | Z14: =INT((X14-MIN($X$2:$X$101))/7)+1 -> 12 | AA14: =IF(X14=MIN($X$2:$X$101),"Lanzamiento","Calendario semanal") -> Calendario semanal
A15: E-14 | B15: Editorial | C15: Más allá de X: dónde debe estar tu marca (X, Threads, Bluesky, LinkedIn) | D15: Redes sociales y comunidad | E15: redes sociales para empresas | F15: Informacional | G15: TOFU | H15: Captar tráfico informacional en «redes sociales para empresas» y construir autoridad temática en redes sociales y comunidad. | I15: General | J15: México + EE.UU. | K15: Re-redacción 2026 | L15: https://www.continentalmedia.com.mx/2022/12/en-que-ha-afectado-la-compra-de-elon-musk-a-la-publicidad-en-twitter/ | M15: https://www.continentalmedia.com.mx/2014/07/estrategias-marca-twitter/ | N15: Mapa de plataformas 2026 por objetivo y tipo de negocio | O15: — | P15: Gestión de redes sociales y community management | Q15: E-11; E-47; G-12; G-17 | R15: Baja | S15: 81 | T15: =CHOOSE(MONTH(X15),"Ene","Feb","Mar","Abr","May","Jun","Jul","Ago","Sep","Oct","Nov","Dic")&" "&YEAR(X15) -> Jun 2027 | W15: Idea | X15: 46567 | Y15: =CHOOSE(WEEKDAY(X15,2),"lunes","martes","miércoles","jueves","viernes","sábado","domingo") -> martes | Z15: =INT((X15-MIN($X$2:$X$101))/7)+1 -> 37 | AA15: =IF(X15=MIN($X$2:$X$101),"Lanzamiento","Calendario semanal") -> Calendario semanal
A16: E-15 | B16: Editorial | C16: Comunidad antes que seguidores: engagement real y contenido viral con propósito | D16: Redes sociales y comunidad | E16: engagement en redes sociales | F16: Informacional | G16: TOFU | H16: Captar tráfico informacional en «engagement en redes sociales» y construir autoridad temática en redes sociales y comunidad. | I16: General | J16: México + EE.UU. | K16: Re-redacción 2026 | L16: https://www.continentalmedia.com.mx/2015/01/conquista-clientes-engagement/ | M16: https://www.continentalmedia.com.mx/2012/12/las-4-r-s-de-las-redes-sociales/ https://www.continentalmedia.com.mx/2015/03/como-atraer-a-tu-publico-objetivo/ https://www.continentalmedia.com.mx/2012/12/marketing-viral/ https://www.continentalmedia.com.mx/2014/09/ice-bucket-challenge/ | N16: De "viralidad" a comunidad; métricas que sí importan | O16: — | P16: Gestión de redes sociales y community management | Q16: E-12; E-13; G-09; G-14 | R16: Media | S16: 33 | T16: =CHOOSE(MONTH(X16),"Ene","Feb","Mar","Abr","May","Jun","Jul","Ago","Sep","Oct","Nov","Dic")&" "&YEAR(X16) -> Ene 2027 | W16: Idea | X16: 46399 | Y16: =CHOOSE(WEEKDAY(X16,2),"lunes","martes","miércoles","jueves","viernes","sábado","domingo") -> martes | Z16: =INT((X16-MIN($X$2:$X$101))/7)+1 -> 13 | AA16: =IF(X16=MIN($X$2:$X$101),"Lanzamiento","Calendario semanal") -> Calendario semanal
A17: E-16 | B17: Editorial | C17: Marketing 360 en 2026: qué significa realmente y por qué sigue funcionando | D17: Estrategia de marketing y contenidos | E17: marketing 360 | F17: Informacional | G17: TOFU | H17: Captar tráfico informacional en «marketing 360» y construir autoridad temática en estrategia de marketing y contenidos. | I17: General | J17: México + EE.UU. | K17: Re-redacción 2026 | L17: https://www.continentalmedia.com.mx/2025/03/marketing-digital-360-como-crear-una-estrategia-integral-para-tu-marca/ | M17: https://www.continentalmedia.com.mx/2016/02/en-que-te-beneficia-el-marketing-de-360o/ https://www.continentalmedia.com.mx/2014/10/marketing-360-grados/ https://www.continentalmedia.com.mx/2016/11/la-imagen-del-marketing-en-que-te-beneficia-el-marketing-360/ | N17: Ampliar con IA, datos propios y medición omnicanal | O17: — | P17: Estrategia de marketing 360 | Q17: E-17; E-18; G-01; G-03 | R17: Alta | S17: 13 | T17: =CHOOSE(MONTH(X17),"Ene","Feb","Mar","Abr","May","Jun","Jul","Ago","Sep","Oct","Nov","Dic")&" "&YEAR(X17) -> Nov 2026 | W17: Idea | X17: 46329 | Y17: =CHOOSE(WEEKDAY(X17,2),"lunes","martes","miércoles","jueves","viernes","sábado","domingo") -> martes | Z17: =INT((X17-MIN($X$2:$X$101))/7)+1 -> 3 | AA17: =IF(X17=MIN($X$2:$X$101),"Lanzamiento","Calendario semanal") -> Calendario semanal
A18: E-17 | B18: Editorial | C18: Marketing digital vs. marketing tradicional: un debate que ya se resolvió | D18: Estrategia de marketing y contenidos | E18: marketing digital vs marketing tradicional | F18: Informacional | G18: TOFU | H18: Captar tráfico informacional en «marketing digital vs marketing tradicional» y construir autoridad temática en estrategia de marketing y contenidos. | I18: General | J18: México + EE.UU. | K18: Re-redacción 2026 | L18: https://www.continentalmedia.com.mx/2013/10/marketing-digital-vs-marketing-tradicional/ | N18: Postura: integración, no sustitución; cuándo usar cada medio | O18: — | P18: Estrategia de marketing 360 | Q18: E-16; E-21; G-05; G-38 | R18: Media | S18: 35 | T18: =CHOOSE(MONTH(X18),"Ene","Feb","Mar","Abr","May","Jun","Jul","Ago","Sep","Oct","Nov","Dic")&" "&YEAR(X18) -> Ene 2027 | W18: Idea | X18: 46406 | Y18: =CHOOSE(WEEKDAY(X18,2),"lunes","martes","miércoles","jueves","viernes","sábado","domingo") -> martes | Z18: =INT((X18-MIN($X$2:$X$101))/7)+1 -> 14 | AA18: =IF(X18=MIN($X$2:$X$101),"Lanzamiento","Calendario semanal") -> Calendario semanal
A19: E-18 | B19: Editorial | C19: Mitos del marketing que en 2026 siguen costándole dinero a las pymes | D19: Estrategia de marketing y contenidos | E19: mitos del marketing | F19: Informacional | G19: TOFU | H19: Captar tráfico informacional en «mitos del marketing» y construir autoridad temática en estrategia de marketing y contenidos. | I19: General | J19: México + EE.UU. | K19: Re-redacción 2026 | L19: https://www.continentalmedia.com.mx/2015/07/5-mitos-del-marketing-que-ya-nadie-debe-creer/ | N19: Lista actualizada: SEO muerto, viral, "más seguidores = más ventas" | O19: — | P19: Estrategia de marketing 360 | Q19: E-16; G-01; G-08 | R19: Media | S19: 37 | T19: =CHOOSE(MONTH(X19),"Ene","Feb","Mar","Abr","May","Jun","Jul","Ago","Sep","Oct","Nov","Dic")&" "&YEAR(X19) -> Ene 2027 | W19: Idea | X19: 46413 | Y19: =CHOOSE(WEEKDAY(X19,2),"lunes","martes","miércoles","jueves","viernes","sábado","domingo") -> martes | Z19: =INT((X19-MIN($X$2:$X$101))/7)+1 -> 15 | AA19: =IF(X19=MIN($X$2:$X$101),"Lanzamiento","Calendario semanal") -> Calendario semanal
A20: E-19 | B20: Editorial | C20: Storytelling de marca: por qué las historias siguen vendiendo en la era del contenido infinito | D20: Estrategia de marketing y contenidos | E20: storytelling de marca | F20: Informacional | G20: TOFU | H20: Captar tráfico informacional en «storytelling de marca» y construir autoridad temática en estrategia de marketing y contenidos. | I20: General | J20: México + EE.UU. | K20: Re-redacción 2026 | L20: https://www.continentalmedia.com.mx/2016/12/storytelling-una-tecnica-para-cautivar-a-tus-clientes/ | N20: Casos de marcas locales; estructura narrativa aplicable | O20: — | P20: Estrategia de marketing 360 | Q20: E-12; E-26; G-09; G-30 | R20: Media | S20: 39 | T20: =CHOOSE(MONTH(X20),"Ene","Feb","Mar","Abr","May","Jun","Jul","Ago","Sep","Oct","Nov","Dic")&" "&YEAR(X20) -> Feb 2027 | W20: Idea | X20: 46420 | Y20: =CHOOSE(WEEKDAY(X20,2),"lunes","martes","miércoles","jueves","viernes","sábado","domingo") -> martes | Z20: =INT((X20-MIN($X$2:$X$101))/7)+1 -> 16 | AA20: =IF(X20=MIN($X$2:$X$101),"Lanzamiento","Calendario semanal") -> Calendario semanal
A21: E-20 | B21: Editorial | C21: Neuromarketing y psicología del color: qué es ciencia y qué es mito | D21: Branding, diseño y creatividad | E21: neuromarketing | F21: Informacional | G21: TOFU | H21: Captar tráfico informacional en «neuromarketing» y construir autoridad temática en branding, diseño y creatividad. | I21: General | J21: México + EE.UU. | K21: Re-redacción 2026 | L21: https://www.continentalmedia.com.mx/2012/12/neuromarketing/ | M21: https://www.continentalmedia.com.mx/2014/04/los-6-colores-que-mas-atraen-en-publicidad/ https://www.continentalmedia.com.mx/2013/06/cual-es-tu-percepcion-del-color/ https://www.continentalmedia.com.mx/2012/08/marketing-olfativo/ https://www.continentalmedia.com.mx/2012/12/por-que-una-imagen-resulta-tan-poderosa/ | N21: Separar evidencia de mitos; color, imagen y olfato | O21: — | P21: Branding, identidad y diseño gráfico | Q21: E-23; E-29; G-40 | R21: Media | S21: 41 | T21: =CHOOSE(MONTH(X21),"Ene","Feb","Mar","Abr","May","Jun","Jul","Ago","Sep","Oct","Nov","Dic")&" "&YEAR(X21) -> Feb 2027 | W21: Idea | X21: 46427 | Y21: =CHOOSE(WEEKDAY(X21,2),"lunes","martes","miércoles","jueves","viernes","sábado","domingo") -> martes | Z21: =INT((X21-MIN($X$2:$X$101))/7)+1 -> 17 | AA21: =IF(X21=MIN($X$2:$X$101),"Lanzamiento","Calendario semanal") -> Calendario semanal
A22: E-21 | B22: Editorial | C22: Invertir en publicidad en tiempos de crisis: por qué las marcas que no recortan ganan | D22: Estrategia de marketing y contenidos | E22: publicidad en tiempos de crisis | F22: Informacional | G22: TOFU | H22: Captar tráfico informacional en «publicidad en tiempos de crisis» y construir autoridad temática en estrategia de marketing y contenidos. | I22: Pymes | J22: México + EE.UU. | K22: Re-redacción 2026 | L22: https://www.continentalmedia.com.mx/2017/01/por-que-invertir-en-publicidad-en-epoca-de-crisis/ | N22: Evidencia histórica y escenarios económicos actuales | O22: — | P22: Estrategia de marketing 360 | Q22: E-17; G-05; G-06 | R22: Media | S22: 43 | T22: =CHOOSE(MONTH(X22),"Ene","Feb","Mar","Abr","May","Jun","Jul","Ago","Sep","Oct","Nov","Dic")&" "&YEAR(X22) -> Feb 2027 | W22: Idea | X22: 46434 | Y22: =CHOOSE(WEEKDAY(X22,2),"lunes","martes","miércoles","jueves","viernes","sábado","domingo") -> martes | Z22: =INT((X22-MIN($X$2:$X$101))/7)+1 -> 18 | AA22: =IF(X22=MIN($X$2:$X$101),"Lanzamiento","Calendario semanal") -> Calendario semanal
A23: E-22 | B23: Editorial | C23: Marketing de contenidos: de producir más a producir mejor | D23: Estrategia de marketing y contenidos | E23: marketing de contenidos | F23: Informacional | G23: TOFU | H23: Captar tráfico informacional en «marketing de contenidos» y construir autoridad temática en estrategia de marketing y contenidos. | I23: General | J23: México + EE.UU. | K23: Re-redacción 2026 | L23: https://www.continentalmedia.com.mx/2017/02/los-beneficios-del-marketing-de-contenidos-para-tu-marca/ | M23: https://www.continentalmedia.com.mx/2019/01/como-hacer-mejor-marketing-de-contenidos/ https://www.continentalmedia.com.mx/2016/10/por-que-son-importantes-las-infografias-en-el-marketing-de-contenidos/ | N23: Del volumen a la calidad: infografías, formatos y reutilización | O23: — | P23: Estrategia de marketing 360 | Q23: G-09; G-36; G-41 | R23: Media | S23: 45 | T23: =CHOOSE(MONTH(X23),"Ene","Feb","Mar","Abr","May","Jun","Jul","Ago","Sep","Oct","Nov","Dic")&" "&YEAR(X23) -> Feb 2027 | W23: Idea | X23: 46441 | Y23: =CHOOSE(WEEKDAY(X23,2),"lunes","martes","miércoles","jueves","viernes","sábado","domingo") -> martes | Z23: =INT((X23-MIN($X$2:$X$101))/7)+1 -> 19 | AA23: =IF(X23=MIN($X$2:$X$101),"Lanzamiento","Calendario semanal") -> Calendario semanal
A24: E-23 | B24: Editorial | C24: Branding en 2026: identidades que funcionan en pantalla, en video y en la era de la IA | D24: Branding, diseño y creatividad | E24: branding tendencias | F24: Informacional | G24: TOFU | H24: Captar tráfico informacional en «branding tendencias» y construir autoridad temática en branding, diseño y creatividad. | I24: General | J24: México + EE.UU. | K24: Nuevo | N24: Sistemas de identidad flexibles; motion y accesibilidad | O24: — | P24: Branding, identidad y diseño gráfico | Q24: E-20; E-24; E-25; E-28; G-26; G-27; G-29; G-30 | R24: Media | S24: 47 | T24: =CHOOSE(MONTH(X24),"Ene","Feb","Mar","Abr","May","Jun","Jul","Ago","Sep","Oct","Nov","Dic")&" "&YEAR(X24) -> Mar 2027 | W24: Idea | X24: 46448 | Y24: =CHOOSE(WEEKDAY(X24,2),"lunes","martes","miércoles","jueves","viernes","sábado","domingo") -> martes | Z24: =INT((X24-MIN($X$2:$X$101))/7)+1 -> 20 | AA24: =IF(X24=MIN($X$2:$X$101),"Lanzamiento","Calendario semanal") -> Calendario semanal
A25: E-24 | B25: Editorial | C25: El logotipo hoy: logos adaptativos, animados y por qué importa tanto | D25: Branding, diseño y creatividad | E25: importancia de un logotipo | F25: Informacional | G25: TOFU | H25: Captar tráfico informacional en «importancia de un logotipo» y construir autoridad temática en branding, diseño y creatividad. | I25: General | J25: México + EE.UU. | K25: Re-redacción 2026 | L25: https://www.continentalmedia.com.mx/2014/07/la-importancia-de-un-logotipo/ | N25: Actualizar con tendencias de logos responsivos y motion | O25: — | P25: Branding, identidad y diseño gráfico | Q25: E-23; G-26; G-28 | R25: Media | S25: 49 | T25: =CHOOSE(MONTH(X25),"Ene","Feb","Mar","Abr","May","Jun","Jul","Ago","Sep","Oct","Nov","Dic")&" "&YEAR(X25) -> Mar 2027 | W25: Idea | X25: 46455 | Y25: =CHOOSE(WEEKDAY(X25,2),"lunes","martes","miércoles","jueves","viernes","sábado","domingo") -> martes | Z25: =INT((X25-MIN($X$2:$X$101))/7)+1 -> 21 | AA25: =IF(X25=MIN($X$2:$X$101),"Lanzamiento","Calendario semanal") -> Calendario semanal
A26: E-25 | B26: Editorial | C26: Branding personal y liderazgo visible: la marca del directivo en LinkedIn | D26: Branding, diseño y creatividad | E26: branding personal | F26: Informacional | G26: TOFU | H26: Captar tráfico informacional en «branding personal» y construir autoridad temática en branding, diseño y creatividad. | I26: Directivos y B2B | J26: México + EE.UU. | K26: Re-redacción 2026 | L26: https://www.continentalmedia.com.mx/2013/07/acerca-del-branding-personal/ | N26: Enfoque B2B: ejecutivos como canal de confianza | O26: — | P26: Branding, identidad y diseño gráfico | Q26: E-23; E-32; G-12 | R26: Media | S26: 51 | T26: =CHOOSE(MONTH(X26),"Ene","Feb","Mar","Abr","May","Jun","Jul","Ago","Sep","Oct","Nov","Dic")&" "&YEAR(X26) -> Mar 2027 | W26: Idea | X26: 46462 | Y26: =CHOOSE(WEEKDAY(X26,2),"lunes","martes","miércoles","jueves","viernes","sábado","domingo") -> martes | Z26: =INT((X26-MIN($X$2:$X$101))/7)+1 -> 22 | AA26: =IF(X26=MIN($X$2:$X$101),"Lanzamiento","Calendario semanal") -> Calendario semanal
A27: E-26 | B27: Editorial | C27: Lovemarks en 2026: cómo se construye una marca que la gente ama | D27: Branding, diseño y creatividad | E27: lovemarks | F27: Informacional | G27: TOFU | H27: Captar tráfico informacional en «lovemarks» y construir autoridad temática en branding, diseño y creatividad. | I27: General | J27: México + EE.UU. | K27: Re-redacción 2026 | L27: https://www.continentalmedia.com.mx/2012/12/lovemarks/ | N27: Emoción, comunidad y consistencia; ejemplos actuales | O27: — | P27: Branding, identidad y diseño gráfico | Q27: E-12; E-19; G-30 | R27: Baja | S27: 83 | T27: =CHOOSE(MONTH(X27),"Ene","Feb","Mar","Abr","May","Jun","Jul","Ago","Sep","Oct","Nov","Dic")&" "&YEAR(X27) -> Jul 2027 | W27: Idea | X27: 46574 | Y27: =CHOOSE(WEEKDAY(X27,2),"lunes","martes","miércoles","jueves","viernes","sábado","domingo") -> martes | Z27: =INT((X27-MIN($X$2:$X$101))/7)+1 -> 38 | AA27: =IF(X27=MIN($X$2:$X$101),"Lanzamiento","Calendario semanal") -> Calendario semanal
A28: E-27 | B28: Editorial | C28: Greenwashing y marketing con propósito: lo que el consumidor ya no tolera | D28: Branding, diseño y creatividad | E28: greenwashing | F28: Informacional | G28: TOFU | H28: Captar tráfico informacional en «greenwashing» y construir autoridad temática en branding, diseño y creatividad. | I28: General | J28: México + EE.UU. | K28: Re-redacción 2026 | L28: https://www.continentalmedia.com.mx/2013/11/greenwashing-el-engano-verde/ | M28: https://www.continentalmedia.com.mx/2013/07/marketing-ecologico-una-decision-responsable/ https://www.continentalmedia.com.mx/2013/10/marketing-social-filantropia-o-estrategia/ https://www.continentalmedia.com.mx/2023/03/el-poder-del-crowdfunding-para-financiar-proyectos-de-beneficencia/ | N28: Regulación y percepción actual; cómo comunicar sostenibilidad con evidencia | O28: — | P28: Branding, identidad y diseño gráfico | Q28: E-28; E-30; E-32; E-35 | R28: Media | S28: 53 | T28: =CHOOSE(MONTH(X28),"Ene","Feb","Mar","Abr","May","Jun","Jul","Ago","Sep","Oct","Nov","Dic")&" "&YEAR(X28) -> Mar 2027 | W28: Idea | X28: 46469 | Y28: =CHOOSE(WEEKDAY(X28,2),"lunes","martes","miércoles","jueves","viernes","sábado","domingo") -> martes | Z28: =INT((X28-MIN($X$2:$X$101))/7)+1 -> 23 | AA28: =IF(X28=MIN($X$2:$X$101),"Lanzamiento","Calendario semanal") -> Calendario semanal
A29: E-28 | B29: Editorial | C29: Co-branding y alianzas de marca: casos, riesgos y lecciones | D29: Branding, diseño y creatividad | E29: co-branding | F29: Informacional | G29: TOFU | H29: Captar tráfico informacional en «co-branding» y construir autoridad temática en branding, diseño y creatividad. | I29: General | J29: México + EE.UU. | K29: Re-redacción 2026 | L29: https://www.continentalmedia.com.mx/2017/03/co-branding-en-que-te-beneficia-asociar-tu-marca-a-otra/ | M29: https://www.continentalmedia.com.mx/2014/08/por-que-la-campana-comparte-una-coca-cola-con-ha-sido-tan-exitosa/ https://www.continentalmedia.com.mx/2013/09/las-marcas-en-el-cine-casualidad-o-causalidad/ | N29: Casos recientes; product placement y colaboraciones | O29: — | P29: Branding, identidad y diseño gráfico | Q29: E-23; E-27; E-46; G-48 | R29: Baja | S29: 85 | T29: =CHOOSE(MONTH(X29),"Ene","Feb","Mar","Abr","May","Jun","Jul","Ago","Sep","Oct","Nov","Dic")&" "&YEAR(X29) -> Jul 2027 | W29: Idea | X29: 46581 | Y29: =CHOOSE(WEEKDAY(X29,2),"lunes","martes","miércoles","jueves","viernes","sábado","domingo") -> martes | Z29: =INT((X29-MIN($X$2:$X$101))/7)+1 -> 39 | AA29: =IF(X29=MIN($X$2:$X$101),"Lanzamiento","Calendario semanal") -> Calendario semanal
A30: E-29 | B30: Editorial | C30: Un diseño bonito no lo es todo: diseño estratégico vs. diseño decorativo | D30: Branding, diseño y creatividad | E30: diseño estratégico | F30: Informacional | G30: TOFU | H30: Captar tráfico informacional en «diseño estratégico» y construir autoridad temática en branding, diseño y creatividad. | I30: General | J30: México + EE.UU. | K30: Re-redacción 2026 | L30: https://www.continentalmedia.com.mx/2013/03/un-diseno-bonito-no-lo-es-todo/ | M30: https://www.continentalmedia.com.mx/2013/05/leyes-gestalt/ https://www.continentalmedia.com.mx/2013/03/porque-invertir-en-imagen-corporativa/ https://www.continentalmedia.com.mx/2013/08/packaging/ | N30: Principios (Gestalt), empaque e imagen corporativa con enfoque de negocio | O30: — | P30: Branding, identidad y diseño gráfico | Q30: E-20; E-39; G-28; G-40 | R30: Media | S30: 55 | T30: =CHOOSE(MONTH(X30),"Ene","Feb","Mar","Abr","May","Jun","Jul","Ago","Sep","Oct","Nov","Dic")&" "&YEAR(X30) -> Mar 2027 | W30: Idea | X30: 46476 | Y30: =CHOOSE(WEEKDAY(X30,2),"lunes","martes","miércoles","jueves","viernes","sábado","domingo") -> martes | Z30: =INT((X30-MIN($X$2:$X$101))/7)+1 -> 24 | AA30: =IF(X30=MIN($X$2:$X$101),"Lanzamiento","Calendario semanal") -> Calendario semanal
A31: E-30 | B31: Editorial | C31: Relaciones públicas en 2026: de la nota de prensa a la reputación digital | D31: Relaciones públicas y comunicación | E31: relaciones públicas | F31: Informacional | G31: TOFU | H31: Captar tráfico informacional en «relaciones públicas» y construir autoridad temática en relaciones públicas y comunicación. | I31: General | J31: México + EE.UU. | K31: Re-redacción 2026 | L31: https://www.continentalmedia.com.mx/2012/12/relaciones-publicas/ | N31: Qué es RP hoy: medios, creadores, reputación online y IA | O31: — | P31: Relaciones públicas y comunicación corporativa | Q31: E-27; G-31; G-32; G-33 | R31: Media | S31: 57 | T31: =CHOOSE(MONTH(X31),"Ene","Feb","Mar","Abr","May","Jun","Jul","Ago","Sep","Oct","Nov","Dic")&" "&YEAR(X31) -> Abr 2027 | W31: Idea | X31: 46483 | Y31: =CHOOSE(WEEKDAY(X31,2),"lunes","martes","miércoles","jueves","viernes","sábado","domingo") -> martes | Z31: =INT((X31-MIN($X$2:$X$101))/7)+1 -> 25 | AA31: =IF(X31=MIN($X$2:$X$101),"Lanzamiento","Calendario semanal") -> Calendario semanal
A32: E-31 | B32: Editorial | C32: Crisis de reputación: lo que enseñan los casos de marcas y figuras públicas | D32: Relaciones públicas y comunicación | E32: crisis de reputación | F32: Informacional | G32: TOFU | H32: Captar tráfico informacional en «crisis de reputación» y construir autoridad temática en relaciones públicas y comunicación. | I32: General | J32: México + EE.UU. | K32: Re-redacción 2026 | L32: https://www.continentalmedia.com.mx/2013/10/crisis-de-imagen-publica-en-el-tri/ | M32: https://www.continentalmedia.com.mx/2015/07/el-gran-error-de-relaciones-publicas-de-donald-trump/ | N32: Casos clásicos y recientes; qué hacer en las primeras 24 horas | O32: — | P32: Relaciones públicas y comunicación corporativa | Q32: E-32; G-14; G-33 | R32: Media | S32: 59 | T32: =CHOOSE(MONTH(X32),"Ene","Feb","Mar","Abr","May","Jun","Jul","Ago","Sep","Oct","Nov","Dic")&" "&YEAR(X32) -> Abr 2027 | W32: Idea | X32: 46490 | Y32: =CHOOSE(WEEKDAY(X32,2),"lunes","martes","miércoles","jueves","viernes","sábado","domingo") -> martes | Z32: =INT((X32-MIN($X$2:$X$101))/7)+1 -> 26 | AA32: =IF(X32=MIN($X$2:$X$101),"Lanzamiento","Calendario semanal") -> Calendario semanal
A33: E-32 | B33: Editorial | C33: Imagen pública: cómo te ven te tratan (marcas y líderes) | D33: Relaciones públicas y comunicación | E33: imagen pública | F33: Informacional | G33: TOFU | H33: Captar tráfico informacional en «imagen pública» y construir autoridad temática en relaciones públicas y comunicación. | I33: General | J33: México + EE.UU. | K33: Re-redacción 2026 | L33: https://www.continentalmedia.com.mx/2016/02/imagen-publica-como-te-ven-te-tratan/ | M33: https://www.continentalmedia.com.mx/2013/06/en-politica-la-imagen-cuenta/ | N33: Percepción, consistencia y coherencia entre discurso y acción | O33: — | P33: Relaciones públicas y comunicación corporativa | Q33: E-25; E-27; E-31; G-34 | R33: Media | S33: 61 | T33: =CHOOSE(MONTH(X33),"Ene","Feb","Mar","Abr","May","Jun","Jul","Ago","Sep","Oct","Nov","Dic")&" "&YEAR(X33) -> Abr 2027 | W33: Idea | X33: 46497 | Y33: =CHOOSE(WEEKDAY(X33,2),"lunes","martes","miércoles","jueves","viernes","sábado","domingo") -> martes | Z33: =INT((X33-MIN($X$2:$X$101))/7)+1 -> 27 | AA33: =IF(X33=MIN($X$2:$X$101),"Lanzamiento","Calendario semanal") -> Calendario semanal
A34: E-33 | B34: Editorial | C34: El proceso creativo en la era de la IA: cómo nacen hoy las buenas ideas | D34: Branding, diseño y creatividad | E34: proceso creativo | F34: Informacional | G34: TOFU | H34: Captar tráfico informacional en «proceso creativo» y construir autoridad temática en branding, diseño y creatividad. | I34: General | J34: México + EE.UU. | K34: Re-redacción 2026 | L34: https://www.continentalmedia.com.mx/2012/12/proceso-creativo/ | M34: https://www.continentalmedia.com.mx/2013/04/10-pasos-para-conseguir-mejores-ideas-creativas/ https://www.continentalmedia.com.mx/2013/04/decalogo-del-valor-de-las-ideas/ https://www.continentalmedia.com.mx/2013/05/cuanto-valen-las-ideas/ https://www.continentalmedia.com.mx/2014/05/no-te-exprimas-el-cerebro-5-ejercicios-para-recuperar-la-creatividad/ https://www.continentalmedia.com.mx/2012/12/churros-creatividad/ | N34: Fusionar cluster de creatividad con enfoque humano + IA | O34: — | P34: Branding, identidad y diseño gráfico | Q34: E-05; E-43; G-19 | R34: Media | S34: 63 | T34: =CHOOSE(MONTH(X34),"Ene","Feb","Mar","Abr","May","Jun","Jul","Ago","Sep","Oct","Nov","Dic")&" "&YEAR(X34) -> Abr 2027 | W34: Idea | X34: 46504 | Y34: =CHOOSE(WEEKDAY(X34,2),"lunes","martes","miércoles","jueves","viernes","sábado","domingo") -> martes | Z34: =INT((X34-MIN($X$2:$X$101))/7)+1 -> 28 | AA34: =IF(X34=MIN($X$2:$X$101),"Lanzamiento","Calendario semanal") -> Calendario semanal
A35: E-34 | B35: Editorial | C35: RP y medios en la era de la IA: cómo cambia el trabajo con la prensa | D35: Relaciones públicas y comunicación | E35: relaciones públicas e inteligencia artificial | F35: Informacional | G35: TOFU | H35: Captar tráfico informacional en «relaciones públicas e inteligencia artificial» y construir autoridad temática en relaciones públicas y comunicación. | I35: General | J35: México + EE.UU. | K35: Nuevo | N35: Periodistas, sala de prensa digital y contenido generado con IA | O35: — | P35: Relaciones públicas y comunicación corporativa | Q35: E-06; E-35; G-31; G-34 | R35: Media | S35: 65 | T35: =CHOOSE(MONTH(X35),"Ene","Feb","Mar","Abr","May","Jun","Jul","Ago","Sep","Oct","Nov","Dic")&" "&YEAR(X35) -> May 2027 | W35: Idea | X35: 46511 | Y35: =CHOOSE(WEEKDAY(X35,2),"lunes","martes","miércoles","jueves","viernes","sábado","domingo") -> martes | Z35: =INT((X35-MIN($X$2:$X$101))/7)+1 -> 29 | AA35: =IF(X35=MIN($X$2:$X$101),"Lanzamiento","Calendario semanal") -> Calendario semanal
A36: E-35 | B36: Editorial | C36: Publicidad responsable: sesgos, estereotipos y mensajes que dañan a tu marca | D36: Relaciones públicas y comunicación | E36: publicidad discriminatoria | F36: Informacional | G36: TOFU | H36: Captar tráfico informacional en «publicidad discriminatoria» y construir autoridad temática en relaciones públicas y comunicación. | I36: General | J36: México + EE.UU. | K36: Re-redacción 2026 | L36: https://www.continentalmedia.com.mx/2014/01/publicidad-discriminatoria/ | M36: https://www.continentalmedia.com.mx/2014/03/por-que-es-polemica-la-publicidad-subliminal/ | N36: Cómo revisar mensajes antes de publicar; casos recientes | O36: — | P36: Relaciones públicas y comunicación corporativa | Q36: E-27; E-34; G-30 | R36: Baja | S36: 87 | T36: =CHOOSE(MONTH(X36),"Ene","Feb","Mar","Abr","May","Jun","Jul","Ago","Sep","Oct","Nov","Dic")&" "&YEAR(X36) -> Jul 2027 | W36: Idea | X36: 46588 | Y36: =CHOOSE(WEEKDAY(X36,2),"lunes","martes","miércoles","jueves","viernes","sábado","domingo") -> martes | Z36: =INT((X36-MIN($X$2:$X$101))/7)+1 -> 40 | AA36: =IF(X36=MIN($X$2:$X$101),"Lanzamiento","Calendario semanal") -> Calendario semanal
A37: E-36 | B37: Editorial | C37: Meta Ads, Google Ads o TikTok Ads: dónde conviene invertir en 2026 | D37: Web, SEO y publicidad digital | E37: diferencias entre Facebook Ads y Google Ads | F37: Comercial | G37: MOFU | H37: Capturar búsquedas de evaluación en «diferencias entre Facebook Ads y Google Ads» y canalizarlas hacia diseño y desarrollo web, seo y publicidad digital. | I37: General | J37: México + EE.UU. | K37: Re-redacción 2026 | L37: https://www.continentalmedia.com.mx/2021/10/diferencias-entre-facebook-ads-y-google-ads/ | N37: Comparativa por objetivo, presupuesto y tipo de negocio | O37: — | P37: Diseño y desarrollo web, SEO y publicidad digital | Q37: G-38; G-39; G-43 | R37: Alta | S37: 15 | T37: =CHOOSE(MONTH(X37),"Ene","Feb","Mar","Abr","May","Jun","Jul","Ago","Sep","Oct","Nov","Dic")&" "&YEAR(X37) -> Nov 2026 | W37: Idea | X37: 46336 | Y37: =CHOOSE(WEEKDAY(X37,2),"lunes","martes","miércoles","jueves","viernes","sábado","domingo") -> martes | Z37: =INT((X37-MIN($X$2:$X$101))/7)+1 -> 4 | AA37: =IF(X37=MIN($X$2:$X$101),"Lanzamiento","Calendario semanal") -> Calendario semanal
A38: E-37 | B38: Editorial | C38: Fin de las cookies y datos propios: cómo medir y vender sin rastreo de terceros | D38: Web, SEO y publicidad digital | E38: first-party data | F38: Informacional | G38: TOFU | H38: Captar tráfico informacional en «first-party data» y construir autoridad temática en web, seo y publicidad digital. | I38: General | J38: México + EE.UU. | K38: Nuevo | N38: Privacidad, consentimiento y estrategia de datos propios | O38: — | P38: Diseño y desarrollo web, SEO y publicidad digital | Q38: G-23; G-42; G-43 | R38: Media | S38: 67 | T38: =CHOOSE(MONTH(X38),"Ene","Feb","Mar","Abr","May","Jun","Jul","Ago","Sep","Oct","Nov","Dic")&" "&YEAR(X38) -> May 2027 | W38: Idea | X38: 46518 | Y38: =CHOOSE(WEEKDAY(X38,2),"lunes","martes","miércoles","jueves","viernes","sábado","domingo") -> martes | Z38: =INT((X38-MIN($X$2:$X$101))/7)+1 -> 30 | AA38: =IF(X38=MIN($X$2:$X$101),"Lanzamiento","Calendario semanal") -> Calendario semanal
A39: E-38 | B39: Editorial | C39: ¿Página de Facebook o sitio web? Por qué tu web sigue siendo tu activo principal | D39: Web, SEO y publicidad digital | E39: página web vs redes sociales | F39: Comercial | G39: MOFU | H39: Capturar búsquedas de evaluación en «página web vs redes sociales» y canalizarlas hacia diseño y desarrollo web, seo y publicidad digital. | I39: General | J39: México + EE.UU. | K39: Re-redacción 2026 | L39: https://www.continentalmedia.com.mx/2014/08/que-es-mejor-para-tu-empresa-una-pagina-de-facebook-o-un-sitio-web/ | M39: https://www.continentalmedia.com.mx/2016/09/la-imagen-del-marketing-sitio-web-o-red-social/ | N39: Argumentos 2026: propiedad de la audiencia, SEO y conversión | O39: — | P39: Diseño y desarrollo web, SEO y publicidad digital | Q39: G-35; G-37; G-40 | R39: Alta | S39: 17 | T39: =CHOOSE(MONTH(X39),"Ene","Feb","Mar","Abr","May","Jun","Jul","Ago","Sep","Oct","Nov","Dic")&" "&YEAR(X39) -> Nov 2026 | W39: Idea | X39: 46343 | Y39: =CHOOSE(WEEKDAY(X39,2),"lunes","martes","miércoles","jueves","viernes","sábado","domingo") -> martes | Z39: =INT((X39-MIN($X$2:$X$101))/7)+1 -> 5 | AA39: =IF(X39=MIN($X$2:$X$101),"Lanzamiento","Calendario semanal") -> Calendario semanal
A40: E-39 | B40: Editorial | C40: Diseño web 2026: tendencias que sí importan (velocidad, accesibilidad, motion, IA) | D40: Web, SEO y publicidad digital | E40: tendencias diseño web | F40: Informacional | G40: TOFU | H40: Captar tráfico informacional en «tendencias diseño web» y construir autoridad temática en web, seo y publicidad digital. | I40: General | J40: México + EE.UU. | K40: Re-redacción 2026 | L40: https://www.continentalmedia.com.mx/2013/03/tendencias-en-diseno-web-2013/ | M40: https://www.continentalmedia.com.mx/2014/04/adaptate-llego-el-diseno-responsivo/ | N40: Reemplaza diseño responsivo 2014 y tendencias 2013 | O40: — | P40: Diseño y desarrollo web, SEO y publicidad digital | Q40: E-08; E-29; E-40; G-35; G-40 | R40: Media | S40: 69 | T40: =CHOOSE(MONTH(X40),"Ene","Feb","Mar","Abr","May","Jun","Jul","Ago","Sep","Oct","Nov","Dic")&" "&YEAR(X40) -> May 2027 | W40: Idea | X40: 46525 | Y40: =CHOOSE(WEEKDAY(X40,2),"lunes","martes","miércoles","jueves","viernes","sábado","domingo") -> martes | Z40: =INT((X40-MIN($X$2:$X$101))/7)+1 -> 31 | AA40: =IF(X40=MIN($X$2:$X$101),"Lanzamiento","Calendario semanal") -> Calendario semanal
...

Sheet Posts actuales
A1: URL actual | B1: Año | C1: Última modificación | D1: Decisión | E1: ID del tema destino | F1: Tema destino | G1: Qué hacer con la URL | H1: Motivo / nota | I1: Fecha de activación del 301
A2: https://www.continentalmedia.com.mx/2012/08/creative-interior-design/ | B2: 2012 | C2: 2019-10-29 | D2: Descartar | F2: =IF(E2="","",IFERROR(INDEX(Backlog!$C$2:$C$101,MATCH(E2,Backlog!$A$2:$A$101,0)),"")) | G2: 410, o 301 a /blog/ o a la categoría más cercana | H2: Contenido de coyuntura/curiosidad o fuera de los servicios actuales | I2: =IF(OR(D2="Consolidar",D2="Re-redactar v2026",D2="Actualizar v2026"),IFERROR(INDEX(Backlog!$X$2:$X$101,MATCH(E2,Backlog!$A$2:$A$101,0)),""),"")
A3: https://www.continentalmedia.com.mx/2012/08/marketing-olfativo/ | B3: 2012 | C3: 2019-10-29 | D3: Consolidar | E3: E-20 | F3: =IF(E3="","",IFERROR(INDEX(Backlog!$C$2:$C$101,MATCH(E3,Backlog!$A$2:$A$101,0)),"")) -> Neuromarketing y psicología del color: qué es ciencia y qué es mito | G3: 301 al nuevo artículo E-20 | H3: Contenido fusionado dentro del tema destino | I3: =IF(OR(D3="Consolidar",D3="Re-redactar v2026",D3="Actualizar v2026"),IFERROR(INDEX(Backlog!$X$2:$X$101,MATCH(E3,Backlog!$A$2:$A$101,0)),""),"") -> 46427
A4: https://www.continentalmedia.com.mx/2012/12/6-razones-pymes-usar-redes-sociales/ | B4: 2012 | C4: 2019-10-22 | D4: Consolidar | E4: E-10 | F4: =IF(E4="","",IFERROR(INDEX(Backlog!$C$2:$C$101,MATCH(E4,Backlog!$A$2:$A$101,0)),"")) -> Alcance orgánico en redes sociales: ¿sigue valiendo la pena para tu empresa? | G4: 301 al nuevo artículo E-10 | H4: Contenido fusionado dentro del tema destino | I4: =IF(OR(D4="Consolidar",D4="Re-redactar v2026",D4="Actualizar v2026"),IFERROR(INDEX(Backlog!$X$2:$X$101,MATCH(E4,Backlog!$A$2:$A$101,0)),""),"") -> 46378
A5: https://www.continentalmedia.com.mx/2012/12/campanas-exitosas-del-2012/ | B5: 2012 | C5: 2019-10-21 | D5: Descartar | F5: =IF(E5="","",IFERROR(INDEX(Backlog!$C$2:$C$101,MATCH(E5,Backlog!$A$2:$A$101,0)),"")) | G5: 410, o 301 a /blog/ o a la categoría más cercana | H5: Contenido de coyuntura/curiosidad o fuera de los servicios actuales | I5: =IF(OR(D5="Consolidar",D5="Re-redactar v2026",D5="Actualizar v2026"),IFERROR(INDEX(Backlog!$X$2:$X$101,MATCH(E5,Backlog!$A$2:$A$101,0)),""),"")
A6: https://www.continentalmedia.com.mx/2012/12/churros-creatividad/ | B6: 2012 | C6: 2019-10-21 | D6: Consolidar | E6: E-33 | F6: =IF(E6="","",IFERROR(INDEX(Backlog!$C$2:$C$101,MATCH(E6,Backlog!$A$2:$A$101,0)),"")) -> El proceso creativo en la era de la IA: cómo nacen hoy las buenas ideas | G6: 301 al nuevo artículo E-33 | H6: Contenido fusionado dentro del tema destino | I6: =IF(OR(D6="Consolidar",D6="Re-redactar v2026",D6="Actualizar v2026"),IFERROR(INDEX(Backlog!$X$2:$X$101,MATCH(E6,Backlog!$A$2:$A$101,0)),""),"") -> 46504
A7: https://www.continentalmedia.com.mx/2012/12/conoce-el-funcionamiento-del-e-mail-marketing/ | B7: 2012 | C7: 2019-10-22 | D7: Re-redactar v2026 | E7: G-42 | F7: =IF(E7="","",IFERROR(INDEX(Backlog!$C$2:$C$101,MATCH(E7,Backlog!$A$2:$A$101,0)),"")) -> Email marketing 2026: estrategia, automatizaciones y entregabilidad | G7: Publicar versión 2026; 301 de la URL antigua a la nueva (o conservar slug) | H7: Fusionar posts de email y mailing; añadir automatización | I7: =IF(OR(D7="Consolidar",D7="Re-redactar v2026",D7="Actualizar v2026"),IFERROR(INDEX(Backlog!$X$2:$X$101,MATCH(E7,Backlog!$A$2:$A$101,0)),""),"") -> 46569
A8: https://www.continentalmedia.com.mx/2012/12/es-necesario-ofrecer-una-buena-atencion-al-cliente-en-las-redes-sociales/ | B8: 2012 | C8: 2019-10-22 | D8: Re-redactar v2026 | E8: G-14 | F8: =IF(E8="","",IFERROR(INDEX(Backlog!$C$2:$C$101,MATCH(E8,Backlog!$A$2:$A$101,0)),"")) -> Cómo responder comentarios negativos y atender clientes en redes sociales | G8: Publicar versión 2026; 301 de la URL antigua a la nueva (o conservar slug) | H8: Protocolos de respuesta y tiempos | I8: =IF(OR(D8="Consolidar",D8="Re-redactar v2026",D8="Actualizar v2026"),IFERROR(INDEX(Backlog!$X$2:$X$101,MATCH(E8,Backlog!$A$2:$A$101,0)),""),"") -> 46499
A9: https://www.continentalmedia.com.mx/2012/12/inversion-publicitaria-en-medios-online/ | B9: 2012 | C9: 2019-10-21 | D9: Consolidar | E9: E-45 | F9: =IF(E9="","",IFERROR(INDEX(Backlog!$C$2:$C$101,MATCH(E9,Backlog!$A$2:$A$101,0)),"")) -> Radio, TV y medios masivos en un plan de medios omnicanal 2026 | G9: 301 al nuevo artículo E-45 | H9: Contenido fusionado dentro del tema destino | I9: =IF(OR(D9="Consolidar",D9="Re-redactar v2026",D9="Actualizar v2026"),IFERROR(INDEX(Backlog!$X$2:$X$101,MATCH(E9,Backlog!$A$2:$A$101,0)),""),"") -> 46616
A10: https://www.continentalmedia.com.mx/2012/12/las-4-r-s-de-las-redes-sociales/ | B10: 2012 | C10: 2019-10-21 | D10: Consolidar | E10: E-15 | F10: =IF(E10="","",IFERROR(INDEX(Backlog!$C$2:$C$101,MATCH(E10,Backlog!$A$2:$A$101,0)),"")) -> Comunidad antes que seguidores: engagement real y contenido viral con propósito | G10: 301 al nuevo artículo E-15 | H10: Contenido fusionado dentro del tema destino | I10: =IF(OR(D10="Consolidar",D10="Re-redactar v2026",D10="Actualizar v2026"),IFERROR(INDEX(Backlog!$X$2:$X$101,MATCH(E10,Backlog!$A$2:$A$101,0)),""),"") -> 46399
A11: https://www.continentalmedia.com.mx/2012/12/lovemarks/ | B11: 2012 | C11: 2019-10-21 | D11: Re-redactar v2026 | E11: E-26 | F11: =IF(E11="","",IFERROR(INDEX(Backlog!$C$2:$C$101,MATCH(E11,Backlog!$A$2:$A$101,0)),"")) -> Lovemarks en 2026: cómo se construye una marca que la gente ama | G11: Publicar versión 2026; 301 de la URL antigua a la nueva (o conservar slug) | H11: Emoción, comunidad y consistencia; ejemplos actuales | I11: =IF(OR(D11="Consolidar",D11="Re-redactar v2026",D11="Actualizar v2026"),IFERROR(INDEX(Backlog!$X$2:$X$101,MATCH(E11,Backlog!$A$2:$A$101,0)),""),"") -> 46574
A12: https://www.continentalmedia.com.mx/2012/12/marketing-de-guerrilla/ | B12: 2012 | C12: 2019-10-21 | D12: Consolidar | E12: E-44 | F12: =IF(E12="","",IFERROR(INDEX(Backlog!$C$2:$C$101,MATCH(E12,Backlog!$A$2:$A$101,0)),"")) -> BTL, guerrilla y experiencias de marca: ideas que funcionan en 2026 | G12: 301 al nuevo artículo E-44 | H12: Contenido fusionado dentro del tema destino | I12: =IF(OR(D12="Consolidar",D12="Re-redactar v2026",D12="Actualizar v2026"),IFERROR(INDEX(Backlog!$X$2:$X$101,MATCH(E12,Backlog!$A$2:$A$101,0)),""),"") -> 46609
A13: https://www.continentalmedia.com.mx/2012/12/marketing-deportivo/ | B13: 2012 | C13: 2019-10-21 | D13: Consolidar | E13: E-46 | F13: =IF(E13="","",IFERROR(INDEX(Backlog!$C$2:$C$101,MATCH(E13,Backlog!$A$2:$A$101,0)),"")) -> Patrocinio de eventos: cómo medir el retorno y elegir bien | G13: 301 al nuevo artículo E-46 | H13: Contenido fusionado dentro del tema destino | I13: =IF(OR(D13="Consolidar",D13="Re-redactar v2026",D13="Actualizar v2026"),IFERROR(INDEX(Backlog!$X$2:$X$101,MATCH(E13,Backlog!$A$2:$A$101,0)),""),"") -> 46623
A14: https://www.continentalmedia.com.mx/2012/12/marketing-viral/ | B14: 2012 | C14: 2019-10-21 | D14: Consolidar | E14: E-15 | F14: =IF(E14="","",IFERROR(INDEX(Backlog!$C$2:$C$101,MATCH(E14,Backlog!$A$2:$A$101,0)),"")) -> Comunidad antes que seguidores: engagement real y contenido viral con propósito | G14: 301 al nuevo artículo E-15 | H14: Contenido fusionado dentro del tema destino | I14: =IF(OR(D14="Consolidar",D14="Re-redactar v2026",D14="Actualizar v2026"),IFERROR(INDEX(Backlog!$X$2:$X$101,MATCH(E14,Backlog!$A$2:$A$101,0)),""),"") -> 46399
A15: https://www.continentalmedia.com.mx/2012/12/neuromarketing/ | B15: 2012 | C15: 2019-10-21 | D15: Re-redactar v2026 | E15: E-20 | F15: =IF(E15="","",IFERROR(INDEX(Backlog!$C$2:$C$101,MATCH(E15,Backlog!$A$2:$A$101,0)),"")) -> Neuromarketing y psicología del color: qué es ciencia y qué es mito | G15: Publicar versión 2026; 301 de la URL antigua a la nueva (o conservar slug) | H15: Separar evidencia de mitos; color, imagen y olfato | I15: =IF(OR(D15="Consolidar",D15="Re-redactar v2026",D15="Actualizar v2026"),IFERROR(INDEX(Backlog!$X$2:$X$101,MATCH(E15,Backlog!$A$2:$A$101,0)),""),"") -> 46427
A16: https://www.continentalmedia.com.mx/2012/12/plan-de-medios/ | B16: 2012 | C16: 2019-10-21 | D16: Consolidar | E16: E-45 | F16: =IF(E16="","",IFERROR(INDEX(Backlog!$C$2:$C$101,MATCH(E16,Backlog!$A$2:$A$101,0)),"")) -> Radio, TV y medios masivos en un plan de medios omnicanal 2026 | G16: 301 al nuevo artículo E-45 | H16: Contenido fusionado dentro del tema destino | I16: =IF(OR(D16="Consolidar",D16="Re-redactar v2026",D16="Actualizar v2026"),IFERROR(INDEX(Backlog!$X$2:$X$101,MATCH(E16,Backlog!$A$2:$A$101,0)),""),"") -> 46616
A17: https://www.continentalmedia.com.mx/2012/12/por-que-una-imagen-resulta-tan-poderosa/ | B17: 2012 | C17: 2019-10-21 | D17: Consolidar | E17: E-20 | F17: =IF(E17="","",IFERROR(INDEX(Backlog!$C$2:$C$101,MATCH(E17,Backlog!$A$2:$A$101,0)),"")) -> Neuromarketing y psicología del color: qué es ciencia y qué es mito | G17: 301 al nuevo artículo E-20 | H17: Contenido fusionado dentro del tema destino | I17: =IF(OR(D17="Consolidar",D17="Re-redactar v2026",D17="Actualizar v2026"),IFERROR(INDEX(Backlog!$X$2:$X$101,MATCH(E17,Backlog!$A$2:$A$101,0)),""),"") -> 46427
