Workbook

Sheet Resumen
A1: Inventario de URLs – continentalmedia.com.mx
A2: Fuente: sitemaps del sitio (generado con script). Fecha de corte: 14/10/2026. Solo URLs publicadas en sitemap; no confirma indexación en Google.
A4: Grupo | B4: Total URLs | C4: Con código HTTP 200 | D4: A revisar (≠200) | E4: Qué contiene
A5: Páginas | B5: =COUNTA(Páginas!A2:A1000)-0 -> 11 | C5: =COUNTIF(Páginas!E2:E1000,200) -> 9 | D5: =B5-C5 -> 2 | E5: Páginas del sitio (home, contacto, servicios, etc.)
A6: Blog | B6: =COUNTA(Blog!A2:A1000)-0 -> 188 | C6: =COUNTIF(Blog!E2:E1000,200) -> 188 | D6: =B6-C6 -> 0 | E6: Entradas del blog
A7: Portafolio | B7: =COUNTA(Portafolio!A2:A1000)-0 -> 216 | C7: =COUNTIF(Portafolio!E2:E1000,200) -> 11 | D7: =B7-C7 -> 205 | E7: Casos del portafolio
A8: Categorías | B8: =COUNTA(Categorías!A2:A1000)-0 -> 38 | C8: =COUNTIF(Categorías!E2:E1000,200) -> 12 | D8: =B8-C8 -> 26 | E8: Categorías de blog, de portafolio y testimonios
A9: Imágenes | B9: =COUNTA(Imágenes!A2:A1000)-0 -> 516 | C9: =COUNTIF(Imágenes!E2:E1000,200) -> 213 | D9: =B9-C9 -> 303 | E9: Páginas de adjuntos (una por imagen); normalmente se redirigen a su página padre
A10: Total | B10: =SUM(B5:B9) -> 969 | C10: =SUM(C5:C9) -> 433 | D10: =SUM(D5:D9) -> 536
A12: Notas
A13: • Duplicados exactos encontrados y eliminados: 0 (se comparó la URL sin mayúsculas, www, barra final ni parámetros). Lo que parecía duplicado son páginas de imágenes (hoja Imágenes) y portafolios con slug -2/-3 (columna Observaciones).
A14: • Las columnas en amarillo (Acción y URL nueva) son para llenar durante la migración.
A15: • Código HTTP ≠ 200: gran parte son errores 500 por saturación del servidor al revisar muchas URLs a la vez. Verifícalas de nuevo antes de decidir.
A16: • "Posible duplicado" = slug con sufijo -2, -3 cuyo original también existe. Revisa antes de eliminar.
A17: • Las columnas de Search Console (impresiones/clics) se quitaron porque estaban vacías; vuelve a agregarlas con el export de Rendimiento > Páginas.
A20: Tratamiento propuesto (versión de transición · 19/10/2026)
A21: Grupo | B21: 301 | C21: 404 | D21: Sin cambio | E21: Total
A22: Páginas | B22: =COUNTIFS('Mapa maestro'!$C$2:$C$970,$A22,'Mapa maestro'!$E$2:$E$970,"301") -> 5 | C22: =COUNTIFS('Mapa maestro'!$C$2:$C$970,$A22,'Mapa maestro'!$E$2:$E$970,"404") -> 5 | D22: =COUNTIFS('Mapa maestro'!$C$2:$C$970,$A22,'Mapa maestro'!$E$2:$E$970,"Sin cambio") -> 1 | E22: =SUM(B22:D22) -> 11
A23: Blog | B23: =COUNTIFS('Mapa maestro'!$C$2:$C$970,$A23,'Mapa maestro'!$E$2:$E$970,"301") -> 161 | C23: =COUNTIFS('Mapa maestro'!$C$2:$C$970,$A23,'Mapa maestro'!$E$2:$E$970,"404") -> 24 | D23: =COUNTIFS('Mapa maestro'!$C$2:$C$970,$A23,'Mapa maestro'!$E$2:$E$970,"Sin cambio") -> 1 | E23: =SUM(B23:D23) -> 186
A24: Portafolio | B24: =COUNTIFS('Mapa maestro'!$C$2:$C$970,$A24,'Mapa maestro'!$E$2:$E$970,"301") -> 216 | C24: =COUNTIFS('Mapa maestro'!$C$2:$C$970,$A24,'Mapa maestro'!$E$2:$E$970,"404") -> 0 | D24: =COUNTIFS('Mapa maestro'!$C$2:$C$970,$A24,'Mapa maestro'!$E$2:$E$970,"Sin cambio") -> 0 | E24: =SUM(B24:D24) -> 216
A25: Categorías | B25: =COUNTIFS('Mapa maestro'!$C$2:$C$970,$A25,'Mapa maestro'!$E$2:$E$970,"301") -> 38 | C25: =COUNTIFS('Mapa maestro'!$C$2:$C$970,$A25,'Mapa maestro'!$E$2:$E$970,"404") -> 0 | D25: =COUNTIFS('Mapa maestro'!$C$2:$C$970,$A25,'Mapa maestro'!$E$2:$E$970,"Sin cambio") -> 0 | E25: =SUM(B25:D25) -> 38
A26: Imágenes | B26: =COUNTIFS('Mapa maestro'!$C$2:$C$970,$A26,'Mapa maestro'!$E$2:$E$970,"301") -> 351 | C26: =COUNTIFS('Mapa maestro'!$C$2:$C$970,$A26,'Mapa maestro'!$E$2:$E$970,"404") -> 165 | D26: =COUNTIFS('Mapa maestro'!$C$2:$C$970,$A26,'Mapa maestro'!$E$2:$E$970,"Sin cambio") -> 0 | E26: =SUM(B26:D26) -> 516
A27: Total | B27: =SUM(B22:B26) -> 771 | C27: =SUM(C22:C26) -> 194 | D27: =SUM(D22:D26) -> 2 | E27: =SUM(E22:E26) -> 967
A29: Blog: qué pasa el día del corte
A30: Indicador | B30: Valor
A31: Fecha de corte (editable en hoja Destinos) | B31: =Destinos!B5 -> 46321
A32: Posts con 301 hacia un artículo | B32: =COUNTIFS('Mapa maestro'!$C$2:$C$970,"Blog",'Mapa maestro'!$F$2:$F$970,"ARTICULO") -> 158
A33: · ya van directo al artículo publicado al corte | B33: =COUNTIFS('Mapa maestro'!$C$2:$C$970,"Blog",'Mapa maestro'!$F$2:$F$970,"ARTICULO",'Mapa maestro'!$I$2:$I$970,"<="&Destinos!B5) -> 21
A34: · van provisionalmente a la categoría o a /blog/ hasta publicar su artículo | B34: =B32-B33 -> 137
A35: Posts descartados (404) | B35: =COUNTIFS('Mapa maestro'!$C$2:$C$970,"Blog",'Mapa maestro'!$E$2:$E$970,"404") -> 24
A36: Última fecha de cambio a destino final (último artículo) | B36: =MAX('Mapa maestro'!$N$2:$N$970) -> 46630
A38: Notas de la versión de transición
A39: • Hojas nuevas: Reglas (criterios), Destinos (rutas y parámetros editables) y Mapa maestro (una fila por URL, fuente para la implementación). Las columnas Acción y URL nueva de cada hoja se leen del Mapa maestro; para cambiar una decisión, editar ahí.
A40: • Host canónico y fecha de corte son supuestos (hoja Destinos). Las rutas /proyectos/, /nosotros/, anclas del home y categorías del blog son propuestas por confirmar con el sitio definitivo.
A41: • Sin datos de Search Console ni de enlaces entrantes no se puede priorizar por valor SEO real: llenar las columnas amarillas Clics y Dominios del Mapa maestro; cualquier 404 con clics o enlaces se marca solo como REVISAR.
A42: • Estados HTTP ≠ 200 del inventario (en su mayoría 500 por saturación al revisar) no cambian el tratamiento: se decide por el tipo de URL, no por el estado del día de la revisión.

Sheet Lista corta
A1: Lista corta de URLs que se atienden en el corte
A2: Criterio: páginas principales + toda URL con 2 o más clics en 16 meses (Search Console, 26-oct-2026) + los 2 posts que se conservan. Todo lo demás del mapa responde 404 con la página personalizada. Destinos y fechas se leen en vivo del Mapa maestro.
A4: # | B4: Ruta origen | C4: Grupo | D4: Clics 16m | E4: Acción final | F4: Ruta destino al corte | G4: Destino final | H4: Fecha de cambio al destino final | I4: Nota
A5: 1 | B5: ='Mapa maestro'!B42 -> /2013/04/historia-de-la-publicidad-en-mexico/ | C5: ='Mapa maestro'!C42 -> Blog | D5: =N('Mapa maestro'!Q42) -> 202 | E5: ='Mapa maestro'!U42 -> 200 · misma URL | F5: ='Mapa maestro'!K42 -> /2013/04/historia-de-la-publicidad-en-mexico/ | G5: ='Mapa maestro'!M42 -> Misma URL: se republica actualizado en el blog nuevo | H5: =IF('Mapa maestro'!N42="","",'Mapa maestro'!N42) | I5: ='Mapa maestro'!P42 -> Junto con el otro post conservado suma el 34% de los clics del sitio viejo; se conserva la ruta heredada (/AAAA/MM/slug/) en el blog nuevo.
A6: 2 | B6: ='Mapa maestro'!B81 -> /2014/02/pioneros-de-la-publicidad-en-mexico/ | C6: ='Mapa maestro'!C81 -> Blog | D6: =N('Mapa maestro'!Q81) -> 48 | E6: ='Mapa maestro'!U81 -> 200 · misma URL | F6: ='Mapa maestro'!K81 -> /2014/02/pioneros-de-la-publicidad-en-mexico/ | G6: ='Mapa maestro'!M81 -> Misma URL: se republica actualizado en el blog nuevo | H6: =IF('Mapa maestro'!N81="","",'Mapa maestro'!N81) | I6: ='Mapa maestro'!P81 -> Junto con el otro post conservado suma el 34% de los clics del sitio viejo; se conserva la ruta heredada (/AAAA/MM/slug/) en el blog nuevo.
A7: 3 | B7: ='Mapa maestro'!B135 -> /2016/11/el-poder-de-la-radio-como-medio-de-comunicacion-publicitaria/ | C7: ='Mapa maestro'!C135 -> Blog | D7: =N('Mapa maestro'!Q135) -> 24 | E7: ='Mapa maestro'!U135 -> 301 | F7: ='Mapa maestro'!K135 -> /blog/ | G7: ='Mapa maestro'!M135 -> Artículo E-45 → /blog/<slug>/ | H7: =IF('Mapa maestro'!N135="","",'Mapa maestro'!N135) -> 46616 | I7: ='Mapa maestro'!P135 -> 0
A8: 4 | B8: ='Mapa maestro'!B46 -> /2013/05/leyes-gestalt/ | C8: ='Mapa maestro'!C46 -> Blog | D8: =N('Mapa maestro'!Q46) -> 21 | E8: ='Mapa maestro'!U46 -> 301 | F8: ='Mapa maestro'!K46 -> /blog/ | G8: ='Mapa maestro'!M46 -> Artículo E-29 → /blog/<slug>/ | H8: =IF('Mapa maestro'!N46="","",'Mapa maestro'!N46) -> 46476 | I8: ='Mapa maestro'!P46 -> 0
A9: 5 | B9: ='Mapa maestro'!B5 -> /contacto/ | C9: ='Mapa maestro'!C5 -> Páginas | D9: =N('Mapa maestro'!Q5) -> 16 | E9: ='Mapa maestro'!U5 -> 301 | F9: ='Mapa maestro'!K5 -> /#contacto | G9: ='Mapa maestro'!M5 -> /#contacto | H9: =IF('Mapa maestro'!N5="","",'Mapa maestro'!N5) | I9: ='Mapa maestro'!P5 -> 0
A10: 6 | B10: ='Mapa maestro'!B350 -> /portfolio/manteleta-para-cata-de-vino/ | C10: ='Mapa maestro'!C350 -> Portafolio | D10: =N('Mapa maestro'!Q350) -> 9 | E10: ='Mapa maestro'!U350 -> 301 | F10: ='Mapa maestro'!K350 -> /proyectos/ | G10: ='Mapa maestro'!M350 -> /proyectos/ | H10: =IF('Mapa maestro'!N350="","",'Mapa maestro'!N350) | I10: ='Mapa maestro'!P350 -> 0
A11: 7 | B11: ='Mapa maestro'!B353 -> /portfolio/organigrama/ | C11: ='Mapa maestro'!C353 -> Portafolio | D11: =N('Mapa maestro'!Q353) -> 9 | E11: ='Mapa maestro'!U353 -> 301 | F11: ='Mapa maestro'!K353 -> /proyectos/ | G11: ='Mapa maestro'!M353 -> /proyectos/ | H11: =IF('Mapa maestro'!N353="","",'Mapa maestro'!N353) | I11: ='Mapa maestro'!P353 -> 0
A12: 8 | B12: ='Mapa maestro'!B120 -> /2015/08/6-secretos-para-diseñar-un-logotipo-exitoso/ | C12: ='Mapa maestro'!C120 -> Blog | D12: =N('Mapa maestro'!Q120) -> 8 | E12: ='Mapa maestro'!U120 -> 301 | F12: ='Mapa maestro'!K120 -> /blog/ | G12: ='Mapa maestro'!M120 -> Artículo G-28 → /blog/<slug>/ | H12: =IF('Mapa maestro'!N120="","",'Mapa maestro'!N120) -> 46527 | I12: ='Mapa maestro'!P120 -> 0
A13: 9 | B13: ='Mapa maestro'!B16 -> /2012/12/campanas-exitosas-del-2012/ | C13: ='Mapa maestro'!C16 -> Blog | D13: =N('Mapa maestro'!Q16) -> 7 | E13: ='Mapa maestro'!U16 -> 301 | F13: ='Mapa maestro'!K16 -> /blog/ | G13: ='Mapa maestro'!M16 -> /blog/ | H13: =IF('Mapa maestro'!N16="","",'Mapa maestro'!N16) | I13: ='Mapa maestro'!P16 -> Descartado en el backlog pero con clics (2 a 7 en 16 meses); decisión: 301 al índice del blog.
A14: 10 | B14: ='Mapa maestro'!B162 -> /2022/01/marketing-para-publico-hispano-en-eeuu/ | C14: ='Mapa maestro'!C162 -> Blog | D14: =N('Mapa maestro'!Q162) -> 7 | E14: ='Mapa maestro'!U162 -> 301 | F14: ='Mapa maestro'!K162 -> /blog/ | G14: ='Mapa maestro'!M162 -> Artículo E-47 → /blog/<slug>/ | H14: =IF('Mapa maestro'!N162="","",'Mapa maestro'!N162) -> 46350 | I14: ='Mapa maestro'!P162 -> 0
A15: 11 | B15: ='Mapa maestro'!B127 -> /2016/04/10-alternativas-de-publicidad-de-paga-en-internet/ | C15: ='Mapa maestro'!C127 -> Blog | D15: =N('Mapa maestro'!Q127) -> 6 | E15: ='Mapa maestro'!U127 -> 301 | F15: ='Mapa maestro'!K127 -> /blog/ | G15: ='Mapa maestro'!M127 -> Artículo G-38 → /blog/<slug>/ | H15: =IF('Mapa maestro'!N127="","",'Mapa maestro'!N127) -> 46408 | I15: ='Mapa maestro'!P127 -> 0
A16: 12 | B16: ='Mapa maestro'!B152 -> /2020/01/10-pasos-para-hacer-un-brief-de-redes-sociales/ | C16: ='Mapa maestro'!C152 -> Blog | D16: =N('Mapa maestro'!Q152) -> 6 | E16: ='Mapa maestro'!U152 -> 301 | F16: ='Mapa maestro'!K152 -> /blog/categoria/estrategia-de-marketing/ | G16: ='Mapa maestro'!M152 -> Artículo G-04 → /blog/<slug>/ | H16: =IF('Mapa maestro'!N152="","",'Mapa maestro'!N152) -> 46457 | I16: ='Mapa maestro'!P152 -> 0
A17: 13 | B17: ='Mapa maestro'!B423 -> /marketing/ | C17: ='Mapa maestro'!C423 -> Categorías | D17: =N('Mapa maestro'!Q423) -> 6 | E17: ='Mapa maestro'!U423 -> 301 | F17: ='Mapa maestro'!K423 -> /blog/categoria/estrategia-de-marketing/ | G17: ='Mapa maestro'!M423 -> /blog/categoria/estrategia-de-marketing/ | H17: =IF('Mapa maestro'!N423="","",'Mapa maestro'!N423) | I17: ='Mapa maestro'!P423 -> Si la categoría nueva aún no tiene artículos al corte, va a /blog/
A18: 14 | B18: ='Mapa maestro'!B309 -> /portfolio/il-veneziano-menu-de-fin-de-ano-2019/ | C18: ='Mapa maestro'!C309 -> Portafolio | D18: =N('Mapa maestro'!Q309) -> 6 | E18: ='Mapa maestro'!U309 -> 301 | F18: ='Mapa maestro'!K309 -> /proyectos/ | G18: ='Mapa maestro'!M309 -> /proyectos/ | H18: =IF('Mapa maestro'!N309="","",'Mapa maestro'!N309) | I18: ='Mapa maestro'!P309 -> 0
A19: 15 | B19: ='Mapa maestro'!B45 -> /2013/05/cuanto-valen-las-ideas/ | C19: ='Mapa maestro'!C45 -> Blog | D19: =N('Mapa maestro'!Q45) -> 5 | E19: ='Mapa maestro'!U45 -> 301 | F19: ='Mapa maestro'!K45 -> /blog/ | G19: ='Mapa maestro'!M45 -> Artículo E-33 → /blog/<slug>/ | H19: =IF('Mapa maestro'!N45="","",'Mapa maestro'!N45) -> 46504 | I19: ='Mapa maestro'!P45 -> 0
A20: 16 | B20: ='Mapa maestro'!B4 -> /agencia-de-publicidad/ | C20: ='Mapa maestro'!C4 -> Páginas | D20: =N('Mapa maestro'!Q4) -> 5 | E20: ='Mapa maestro'!U4 -> 301 | F20: ='Mapa maestro'!K4 -> / | G20: ='Mapa maestro'!M4 -> / | H20: =IF('Mapa maestro'!N4="","",'Mapa maestro'!N4) | I20: ='Mapa maestro'!P4 -> Landing con la keyword «agencia de publicidad»: reflejarla en title/H1 del home nuevo
A21: 17 | B21: ='Mapa maestro'!B12 -> /usa/ | C21: ='Mapa maestro'!C12 -> Páginas | D21: =N('Mapa maestro'!Q12) -> 5 | E21: ='Mapa maestro'!U12 -> 301 | F21: ='Mapa maestro'!K12 -> / | G21: ='Mapa maestro'!M12 -> / | H21: =IF('Mapa maestro'!N12="","",'Mapa maestro'!N12) | I21: ='Mapa maestro'!P12 -> Revisar contenido original (HTTP 500 en la revisión). Candidata a tema E-47 (consumidor hispano en EE.UU.) cuando se publique
A22: 18 | B22: ='Mapa maestro'!B104 -> /2014/08/por-que-la-campana-comparte-una-coca-cola-con-ha-sido-tan-exitosa/ | C22: ='Mapa maestro'!C104 -> Blog | D22: =N('Mapa maestro'!Q104) -> 4 | E22: ='Mapa maestro'!U104 -> 301 | F22: ='Mapa maestro'!K104 -> /blog/ | G22: ='Mapa maestro'!M104 -> Artículo E-28 → /blog/<slug>/ | H22: =IF('Mapa maestro'!N104="","",'Mapa maestro'!N104) -> 46581 | I22: ='Mapa maestro'!P104 -> 0
A23: 19 | B23: ='Mapa maestro'!B28 -> /2012/12/por-que-una-imagen-resulta-tan-poderosa/ | C23: ='Mapa maestro'!C28 -> Blog | D23: =N('Mapa maestro'!Q28) -> 3 | E23: ='Mapa maestro'!U28 -> 301 | F23: ='Mapa maestro'!K28 -> /blog/ | G23: ='Mapa maestro'!M28 -> Artículo E-20 → /blog/<slug>/ | H23: =IF('Mapa maestro'!N28="","",'Mapa maestro'!N28) -> 46427 | I23: ='Mapa maestro'!P28 -> 0
A24: 20 | B24: ='Mapa maestro'!B168 -> /2022/05/que-es-uber-one-nosotros-te-lo-explicamos/ | C24: ='Mapa maestro'!C168 -> Blog | D24: =N('Mapa maestro'!Q168) -> 3 | E24: ='Mapa maestro'!U168 -> 301 | F24: ='Mapa maestro'!K168 -> /blog/ | G24: ='Mapa maestro'!M168 -> /blog/ | H24: =IF('Mapa maestro'!N168="","",'Mapa maestro'!N168) | I24: ='Mapa maestro'!P168 -> Descartado en el backlog pero con clics (2 a 7 en 16 meses); decisión: 301 al índice del blog.
A25: 21 | B25: ='Mapa maestro'!B192 -> /2023/12/guia-de-publicidad-para-fin-de-ano/ | C25: ='Mapa maestro'!C192 -> Blog | D25: =N('Mapa maestro'!Q192) -> 3 | E25: ='Mapa maestro'!U192 -> 301 | F25: ='Mapa maestro'!K192 -> [artículo G-07] /blog/<slug>/ | G25: ='Mapa maestro'!M192 -> Artículo G-07 → /blog/<slug>/ | H25: =IF('Mapa maestro'!N192="","",'Mapa maestro'!N192) -> 46314 | I25: ='Mapa maestro'!P192 -> 0
A26: 22 | B26: ='Mapa maestro'!B10 -> /portafolio/ | C26: ='Mapa maestro'!C10 -> Páginas | D26: =N('Mapa maestro'!Q10) -> 3 | E26: ='Mapa maestro'!U10 -> 301 | F26: ='Mapa maestro'!K10 -> /proyectos/ | G26: ='Mapa maestro'!M10 -> /proyectos/ | H26: =IF('Mapa maestro'!N10="","",'Mapa maestro'!N10) | I26: ='Mapa maestro'!P10 -> 0
A27: 23 | B27: ='Mapa maestro'!B73 -> /2013/12/las-campanas-mexicanas-mas-premiadas-de-2013/ | C27: ='Mapa maestro'!C73 -> Blog | D27: =N('Mapa maestro'!Q73) -> 2 | E27: ='Mapa maestro'!U73 -> 301 | F27: ='Mapa maestro'!K73 -> /blog/ | G27: ='Mapa maestro'!M73 -> /blog/ | H27: =IF('Mapa maestro'!N73="","",'Mapa maestro'!N73) | I27: ='Mapa maestro'!P73 -> Descartado en el backlog pero con clics (2 a 7 en 16 meses); decisión: 301 al índice del blog.
A28: 24 | B28: ='Mapa maestro'!B121 -> /2015/09/la-tercera-edad-el-nicho-de-mercado-inesperado/ | C28: ='Mapa maestro'!C121 -> Blog | D28: =N('Mapa maestro'!Q121) -> 2 | E28: ='Mapa maestro'!U121 -> 301 | F28: ='Mapa maestro'!K121 -> /blog/ | G28: ='Mapa maestro'!M121 -> Artículo E-49 → /blog/<slug>/ | H28: =IF('Mapa maestro'!N121="","",'Mapa maestro'!N121) -> 46630 | I28: ='Mapa maestro'!P121 -> 0
A29: 25 | B29: ='Mapa maestro'!B137 -> /2016/12/el-patrocinio-de-eventos-una-estrategia-clave-para-tu-marca/ | C29: ='Mapa maestro'!C137 -> Blog | D29: =N('Mapa maestro'!Q137) -> 2 | E29: ='Mapa maestro'!U137 -> 301 | F29: ='Mapa maestro'!K137 -> /blog/ | G29: ='Mapa maestro'!M137 -> Artículo E-46 → /blog/<slug>/ | H29: =IF('Mapa maestro'!N137="","",'Mapa maestro'!N137) -> 46623 | I29: ='Mapa maestro'!P137 -> 0
A30: 26 | B30: ='Mapa maestro'!B148 -> /2018/03/como-hacer-un-giveaway-en-5-sencillos-pasos/ | C30: ='Mapa maestro'!C148 -> Blog | D30: =N('Mapa maestro'!Q148) -> 2 | E30: ='Mapa maestro'!U148 -> 301 | F30: ='Mapa maestro'!K148 -> /blog/categoria/redes-sociales/ | G30: ='Mapa maestro'!M148 -> Artículo G-13 → /blog/<slug>/ | H30: =IF('Mapa maestro'!N148="","",'Mapa maestro'!N148) -> 46604 | I30: ='Mapa maestro'!P148 -> 0
A31: 27 | B31: ='Mapa maestro'!B193 -> /2024/01/10-tips-para-optimizar-tus-ads-de-facebook-en-2024/ | C31: ='Mapa maestro'!C193 -> Blog | D31: =N('Mapa maestro'!Q193) -> 2 | E31: ='Mapa maestro'!U193 -> 301 | F31: ='Mapa maestro'!K193 -> /blog/ | G31: ='Mapa maestro'!M193 -> Artículo G-39 → /blog/<slug>/ | H31: =IF('Mapa maestro'!N193="","",'Mapa maestro'!N193) -> 46415 | I31: ='Mapa maestro'!P193 -> 0
A32: 28 | B32: ='Mapa maestro'!B195 -> /2025/07/como-aprovechar-la-inteligencia-artificial-en-el-marketing-6-herramientas-que-transformaran-tu-negocio/ | C32: ='Mapa maestro'!C195 -> Blog | D32: =N('Mapa maestro'!Q195) -> 2 | E32: ='Mapa maestro'!U195 -> 301 | F32: ='Mapa maestro'!K195 -> /blog/categoria/ia-aplicada-al-marketing/ | G32: ='Mapa maestro'!M195 -> Artículo G-22 → /blog/<slug>/ | H32: =IF('Mapa maestro'!N195="","",'Mapa maestro'!N195) -> 46513 | I32: ='Mapa maestro'!P195 -> Post de 2025: conviene adelantar su artículo destino en el calendario
A33: 29 | B33: ='Mapa maestro'!B421 -> /inteligencia-artificial/ | C33: ='Mapa maestro'!C421 -> Categorías | D33: =N('Mapa maestro'!Q421) -> 2 | E33: ='Mapa maestro'!U421 -> 301 | F33: ='Mapa maestro'!K421 -> /blog/categoria/ia-aplicada-al-marketing/ | G33: ='Mapa maestro'!M421 -> /blog/categoria/ia-aplicada-al-marketing/ | H33: =IF('Mapa maestro'!N421="","",'Mapa maestro'!N421) | I33: ='Mapa maestro'!P421 -> Si la categoría nueva aún no tiene artículos al corte, va a /blog/
A34: 30 | B34: ='Mapa maestro'!B8 -> /nuestros-servicios/ | C34: ='Mapa maestro'!C8 -> Páginas | D34: =N('Mapa maestro'!Q8) -> 2 | E34: ='Mapa maestro'!U8 -> 301 | F34: ='Mapa maestro'!K8 -> /#servicios | G34: ='Mapa maestro'!M8 -> /#servicios | H34: =IF('Mapa maestro'!N8="","",'Mapa maestro'!N8) | I34: ='Mapa maestro'!P8 -> 0
A35: 31 | B35: ='Mapa maestro'!B822 -> /portfolio/estanciaboca/provisa-espectacular/ | C35: ='Mapa maestro'!C822 -> Imágenes | D35: =N('Mapa maestro'!Q822) -> 2 | E35: ='Mapa maestro'!U822 -> 301 | F35: ='Mapa maestro'!K822 -> /proyectos/ | G35: ='Mapa maestro'!M822 -> /proyectos/ | H35: =IF('Mapa maestro'!N822="","",'Mapa maestro'!N822) | I35: ='Mapa maestro'!P822 -> 0
A36: 32 | B36: ='Mapa maestro'!B287 -> /portfolio/fraccionamiento-albatros-anuncio-periodico/ | C36: ='Mapa maestro'!C287 -> Portafolio | D36: =N('Mapa maestro'!Q287) -> 2 | E36: ='Mapa maestro'!U287 -> 301 | F36: ='Mapa maestro'!K287 -> /proyectos/ | G36: ='Mapa maestro'!M287 -> /proyectos/ | H36: =IF('Mapa maestro'!N287="","",'Mapa maestro'!N287) | I36: ='Mapa maestro'!P287 -> 0
A37: 33 | B37: ='Mapa maestro'!B288 -> /portfolio/fraccionamiento-albatros-fryer/ | C37: ='Mapa maestro'!C288 -> Portafolio | D37: =N('Mapa maestro'!Q288) -> 2 | E37: ='Mapa maestro'!U288 -> 301 | F37: ='Mapa maestro'!K288 -> /proyectos/ | G37: ='Mapa maestro'!M288 -> /proyectos/ | H37: =IF('Mapa maestro'!N288="","",'Mapa maestro'!N288) | I37: ='Mapa maestro'!P288 -> 0
A38: 34 | B38: ='Mapa maestro'!B297 -> /portfolio/hoja-membretada-vermara/ | C38: ='Mapa maestro'!C297 -> Portafolio | D38: =N('Mapa maestro'!Q297) -> 2 | E38: ='Mapa maestro'!U297 -> 301 | F38: ='Mapa maestro'!K297 -> /proyectos/ | G38: ='Mapa maestro'!M297 -> /proyectos/ | H38: =IF('Mapa maestro'!N297="","",'Mapa maestro'!N297) | I38: ='Mapa maestro'!P297 -> 0
A39: 35 | B39: ='Mapa maestro'!B321 -> /portfolio/la-hilacha-logotipo/ | C39: ='Mapa maestro'!C321 -> Portafolio | D39: =N('Mapa maestro'!Q321) -> 2 | E39: ='Mapa maestro'!U321 -> 301 | F39: ='Mapa maestro'!K321 -> /proyectos/ | G39: ='Mapa maestro'!M321 -> /proyectos/ | H39: =IF('Mapa maestro'!N321="","",'Mapa maestro'!N321) | I39: ='Mapa maestro'!P321 -> 0
A40: 36 | B40: ='Mapa maestro'!B333 -> /portfolio/logo-porteadores-del-centro-de-veracruz/ | C40: ='Mapa maestro'!C333 -> Portafolio | D40: =N('Mapa maestro'!Q333) -> 2 | E40: ='Mapa maestro'!U333 -> 301 | F40: ='Mapa maestro'!K333 -> /proyectos/ | G40: ='Mapa maestro'!M333 -> /proyectos/ | H40: =IF('Mapa maestro'!N333="","",'Mapa maestro'!N333) | I40: ='Mapa maestro'!P333 -> 0
A41: 37 | B41: ='Mapa maestro'!B405 -> /portfolio/triptico-cetis-15/ | C41: ='Mapa maestro'!C405 -> Portafolio | D41: =N('Mapa maestro'!Q405) -> 2 | E41: ='Mapa maestro'!U405 -> 301 | F41: ='Mapa maestro'!K405 -> /proyectos/ | G41: ='Mapa maestro'!M405 -> /proyectos/ | H41: =IF('Mapa maestro'!N405="","",'Mapa maestro'!N405) | I41: ='Mapa maestro'!P405 -> 0
...

Sheet Reglas
A1: Reglas de tratamiento por tipo de URL
A3: Regla | B3: Tipo de URL | C3: URLs | D3: Tratamiento | E3: Destino | F3: Por qué
A4: R-PAG-01 | B4: Home | C4: =COUNTIF('Mapa maestro'!$O$2:$O$970,A4) -> 1 | D4: Sin cambio | E4: Home nuevo (solo se normaliza host/https) | F4: Es el equivalente directo.
A5: R-PAG-02 | B5: Páginas con equivalente: contacto, nuestros-servicios, portafolio | C5: =COUNTIF('Mapa maestro'!$O$2:$O$970,A5) -> 3 | D5: 301 | E5: Sección equivalente del sitio nuevo | F5: Una página vieja → su equivalente más cercano (1 a 1).
A6: R-PAG-03 | B6: Páginas técnicas/de prueba (404-page, elementor-3504, homepage-revolution, pagina-inicial, testing-1) | C6: =COUNTIF('Mapa maestro'!$O$2:$O$970,A6) -> 5 | D6: 404 | E6: Página 404 personalizada | F6: No tienen valor SEO ni equivalente; redirigirlas al home las convertiría en soft 404.
A7: R-PAG-04 | B7: Landings sin equivalente exacto: agencia-de-publicidad, usa | C7: =COUNTIF('Mapa maestro'!$O$2:$O$970,A7) -> 2 | D7: 301 | E7: Home | F7: Revisar su contenido; si /usa/ tenía tráfico, se puede reasignar al tema E-47.
A8: R-BLOG-01 | B8: Posts con tema equivalente (re-redactar, actualizar, consolidar, mantener) | C8: =COUNTIF('Mapa maestro'!$O$2:$O$970,A8) -> 158 | D8: 301 | E8: Artículo del tema; antes de que se publique: categoría del pilar o /blog/ | F8: Hereda la señal del post al artículo que lo reemplaza; mientras tanto va al destino temático más cercano.
A9: R-BLOG-02 | B9: Posts descartados (sin valor SEO actual) | C9: =COUNTIF('Mapa maestro'!$O$2:$O$970,A9) -> 24 | D9: 404 | E9: Página 404 personalizada | F9: Evita mandar contenido no relacionado a un destino irrelevante.
A10: R-BLOG-03 | B10: Índice /blog/ | C10: =COUNTIF('Mapa maestro'!$O$2:$O$970,A10) -> 1 | D10: Sin cambio | E10: Índice del blog nuevo (misma ruta) | F10: La misma URL se conserva.
A11: R-POR-01 | B11: Piezas del portafolio | C11: =COUNTIF('Mapa maestro'!$O$2:$O$970,A11) -> 216 | D11: 301 | E11: /proyectos/ | F11: Mismo propósito (portafolio → portafolio). Requiere una página real; no un ancla del home.
A12: R-CAT-01 | B12: Categorías del blog | C12: =COUNTIF('Mapa maestro'!$O$2:$O$970,A12) -> 24 | D12: 301 | E12: Categoría del pilar equivalente (o /blog/) | F12: Temática equivalente; si la categoría aún no tiene artículos al corte, se usa /blog/.
A13: R-CAT-02 | B13: Categorías de portafolio | C13: =COUNTIF('Mapa maestro'!$O$2:$O$970,A13) -> 11 | D13: 301 | E13: /proyectos/ | F13: Mismo propósito.
A14: R-TES-01 | B14: Testimonios individuales | C14: =COUNTIF('Mapa maestro'!$O$2:$O$970,A14) -> 3 | D14: 301 | E14: Sección Testimonios | F14: Equivalente temático (solo 3 URLs).
A15: R-IMG-01 | B15: Páginas de adjuntos con padre redirigible | C15: =COUNTIF('Mapa maestro'!$O$2:$O$970,A15) -> 351 | D15: 301 | E15: Destino final de su página padre (sin cadenas) | F15: Son páginas delgadas de WordPress; siguen a su padre.
A16: R-IMG-02 | B16: Páginas de adjuntos sin padre o con padre en 404 | C16: =COUNTIF('Mapa maestro'!$O$2:$O$970,A16) -> 165 | D16: 404 | E16: Página 404 personalizada | F16: Sin contenido propio que heredar.
B17: Total | C17: =SUM(C4:C16) -> 964
A19: Reglas globales (URLs que no están en el inventario)
A20: Patrón | B20: Qué es | D20: Tratamiento | E20: Destino | F20: Nota
A21: http:// → https:// y www → host canónico | B21: Normalización de host | D21: 301 | E21: Misma ruta en el host canónico | F21: En un solo salto junto con el mapa (sin cadenas).
A22: Mayúsculas y ruta sin barra final | B22: Variantes de las URLs del mapa | D22: 301 | E22: Igual que su URL con barra final | F22: Las reglas deben ser insensibles a mayúsculas y tolerar la barra final.
A23: /feed/ · /*/feed/ · /comments/feed/ | B23: Feeds RSS de WordPress | D23: 301 | E23: /blog/feed.xml (o el feed nuevo) | F23: Conserva a los suscriptores de RSS.
A24: /sitemap_index.xml · /wp-sitemap.xml · /post-sitemap.xml · /page-sitemap.xml | B24: Sitemaps viejos | D24: 301 | E24: /sitemap.xml | F24: Google puede mostrar avisos de redirect en sitemaps viejos; es normal.
A25: /wp-content/uploads/* | B25: Archivos de imagen y PDF del sitio viejo | D25: 404 | E25: Página 404 | F25: Revisar en Search Console (imágenes) si alguno tiene tráfico y migrarlo a mano.
A26: /wp-admin/* · /wp-login.php · /xmlrpc.php · /wp-json/* | B26: Rutas técnicas de WordPress | D26: 404 | E26: Página 404 | F26: Los bots las seguirán pidiendo; no dar redirect.
A27: /tag/* · /author/* · /category/* · /page/N/ | B27: Archivos de WordPress | D27: 404 | E27: Página 404 | F27: No están en el sitemap; sin valor. /blog/page/N/ del blog nuevo conserva su ruta.
A28: Parámetros ?s= · ?p=ID · ?utm_ | B28: Búsquedas internas y enlaces cortos | D28: — | E28: Sin regla | F28: Los hosts estáticos no pueden hacer match por parámetros; el 404 sugiere a dónde ir.

Sheet Destinos
A1: Destinos del sitio nuevo y parámetros
A2: Editar solo las celdas azules/amarillas. Todo el Mapa maestro se recalcula desde aquí.
A4: Host canónico (sin barra final) | B4: https://continentalmedia.com.mx | C4: Supuesto: el sitio temporal declara el dominio sin www como canonical. Si se prefiere www, cambiar aquí y en el sitio.
A5: Fecha de corte (cambio de DNS) | B5: 46321 | C5: Supuesto editable: define qué artículos y categorías ya existen cuando se activan las redirecciones.
A8: Código | B8: Sección destino | C8: Ruta propuesta | D8: Estado de la ruta | E8: Pilar (backlog) | F8: Primera publicación | G8: ¿Existe al corte? | H8: Ruta efectiva al corte | I8: Nota
A9: HOME | B9: Inicio | C9: / | D9: Confirmada | G9: =IF(F9="",TRUE(),F9<=$B$5) -> TRUE | H9: =IF(G9,C9,$C$15) -> /
A10: SERVICIOS | B10: Servicios (sección del home) | C10: /#servicios | D10: Por confirmar | G10: =IF(F10="",TRUE(),F10<=$B$5) -> TRUE | H10: =IF(G10,C10,$C$15) -> /#servicios | I10: Ancla: Google ignora el #; para SEO cuenta la página. Alternativa: /servicios/ como página real.
A11: PROYECTOS | B11: Proyectos (página real recomendada) | C11: /proyectos/ | D11: Por crear | G11: =IF(F11="",TRUE(),F11<=$B$5) -> TRUE | H11: =IF(G11,C11,$C$15) -> /proyectos/ | I11: Recomendado: crear /proyectos/ como página real (indexable). Con ancla en el home, Google puede tratar ~230 redirects como soft 404.
A12: TESTIMONIOS | B12: Testimonios (sección del home) | C12: /#testimonios | D12: Por confirmar | G12: =IF(F12="",TRUE(),F12<=$B$5) -> TRUE | H12: =IF(G12,C12,$C$15) -> /#testimonios | I12: Solo 3 URLs; ancla del home es suficiente.
A13: NOSOTROS | B13: Nosotros | C13: /nosotros/ | D13: Por confirmar | G13: =IF(F13="",TRUE(),F13<=$B$5) -> TRUE | H13: =IF(G13,C13,$C$15) -> /nosotros/ | I13: El sitio temporal usa nosotros.html; confirmar la ruta final.
A14: CONTACTO | B14: Contacto (sección del home) | C14: /#contacto | D14: Por confirmar | G14: =IF(F14="",TRUE(),F14<=$B$5) -> TRUE | H14: =IF(G14,C14,$C$15) -> /#contacto
A15: BLOG | B15: Blog · índice | C15: /blog/ | D15: Por construir | G15: =IF(F15="",TRUE(),F15<=$B$5) -> TRUE | H15: =IF(G15,C15,$C$15) -> /blog/ | I15: Índice con la misma ruta que hoy.
A16: CAT_P1 | B16: Blog · Estrategia de marketing y contenidos | C16: /blog/categoria/estrategia-de-marketing/ | D16: Por construir | E16: Estrategia de marketing y contenidos | F16: 46314 | G16: =IF(F16="",TRUE(),F16<=$B$5) -> TRUE | H16: =IF(G16,C16,$C$15) -> /blog/categoria/estrategia-de-marketing/
A17: CAT_P2 | B17: Blog · Redes sociales y comunidad | C17: /blog/categoria/redes-sociales/ | D17: Por construir | E17: Redes sociales y comunidad | F17: 46314 | G17: =IF(F17="",TRUE(),F17<=$B$5) -> TRUE | H17: =IF(G17,C17,$C$15) -> /blog/categoria/redes-sociales/
A18: CAT_P3 | B18: Blog · IA aplicada al marketing | C18: /blog/categoria/ia-aplicada-al-marketing/ | D18: Por construir | E18: IA aplicada al marketing | F18: 46314 | G18: =IF(F18="",TRUE(),F18<=$B$5) -> TRUE | H18: =IF(G18,C18,$C$15) -> /blog/categoria/ia-aplicada-al-marketing/
A19: CAT_P4 | B19: Blog · Branding, diseño y creatividad | C19: /blog/categoria/branding-y-diseno/ | D19: Por construir | E19: Branding, diseño y creatividad | F19: 46366 | G19: =IF(F19="",TRUE(),F19<=$B$5) -> FALSE | H19: =IF(G19,C19,$C$15) -> /blog/
A20: CAT_P5 | B20: Blog · Relaciones públicas y comunicación | C20: /blog/categoria/relaciones-publicas/ | D20: Por construir | E20: Relaciones públicas y comunicación | F20: 46373 | G20: =IF(F20="",TRUE(),F20<=$B$5) -> FALSE | H20: =IF(G20,C20,$C$15) -> /blog/
A21: CAT_P6 | B21: Blog · Web, SEO y publicidad digital | C21: /blog/categoria/web-seo-y-publicidad/ | D21: Por construir | E21: Web, SEO y publicidad digital | F21: 46336 | G21: =IF(F21="",TRUE(),F21<=$B$5) -> FALSE | H21: =IF(G21,C21,$C$15) -> /blog/
A22: CAT_P7 | B22: Blog · Video y fotografía | C22: /blog/categoria/video-y-fotografia/ | D22: Por construir | E22: Video y fotografía | F22: 46532 | G22: =IF(F22="",TRUE(),F22<=$B$5) -> FALSE | H22: =IF(G22,C22,$C$15) -> /blog/
A23: CAT_P8 | B23: Blog · Eventos, medios y publicidad exterior | C23: /blog/categoria/eventos-y-medios/ | D23: Por construir | E23: Eventos, medios y publicidad exterior | F23: 46609 | G23: =IF(F23="",TRUE(),F23<=$B$5) -> FALSE | H23: =IF(G23,C23,$C$15) -> /blog/
A24: CAT_P9 | B24: Blog · Marketing por industria y mercado | C24: /blog/categoria/marketing-por-industria/ | D24: Por construir | E24: Marketing por industria y mercado | F24: 46350 | G24: =IF(F24="",TRUE(),F24<=$B$5) -> FALSE | H24: =IF(G24,C24,$C$15) -> /blog/
A25: ARTICULO | B25: Artículo del tema (slug definido al publicar) | C25: /blog/<slug>/ | D25: Por construir | G25: =IF(F25="",TRUE(),F25<=$B$5) -> TRUE | H25: =IF(G25,C25,$C$15) -> /blog/<slug>/ | I25: Cada redirect de blog apunta al artículo de su tema cuando este se publica; antes va a la categoría del pilar o a /blog/.

Sheet Mapa maestro
A1: URL origen | B1: Ruta origen | C1: Grupo | D1: Página padre (imágenes) | E1: Acción | F1: Destino lógico | G1: ID tema destino | H1: Pilar del tema | I1: Fecha publicación del tema | J1: Código HTTP | K1: Ruta destino al corte | L1: URL nueva al corte | M1: Destino final | N1: Fecha de cambio al destino final | O1: Regla | P1: Nota | Q1: Clics 16m (Search Console) | R1: Dominios que enlazan | S1: Alerta | T1: ¿Entra en la lista corta? | U1: Acción final (plan reducido)
A2: https://www.continentalmedia.com.mx/ | B2: / | C2: Páginas | E2: Sin cambio | F2: HOME | J2: =IF(E2="301",301,IF(E2="404",404,200)) -> 200 | K2: =IF($E2="404","",IF($F2="ARTICULO",IF($I2<=Destinos!$B$5,"[artículo "&$G2&"] /blog/<slug>/",IFERROR(INDEX(Destinos!$H$9:$H$25,MATCH($H2,Destinos!$E$9:$E$25,0)),Destinos!$C$15)),INDEX(Destinos!$H$9:$H$25,MATCH($F2,Destinos!$A$9:$A$25,0)))) -> / | L2: =IF($K2="","",IF(LEFT($K2,1)="/",Destinos!$B$4&$K2,$K2)) -> https://continentalmedia.com.mx/ | M2: =IF($E2="404","",IF($F2="ARTICULO","Artículo "&$G2&" → /blog/<slug>/",INDEX(Destinos!$C$9:$C$25,MATCH($F2,Destinos!$A$9:$A$25,0)))) -> / | N2: =IF(AND($E2="301",$F2="ARTICULO"),$I2,"") | O2: R-PAG-01 | P2: Equivalente directo (solo normaliza host/https) | Q2: 222 | S2: =IF(AND($E2="404",OR(N($Q2)>0,N($R2)>0)),"REVISAR: tiene clics o enlaces → pasar a 301","") | T2: =IF(OR($E2="Conservar URL",AND($E2="301",OR(N($Q2)>=2,$C2="Páginas"))),"Sí","No") -> No | U2: =IF($E2="Sin cambio","200 · sin cambio",IF($T2="Sí",IF($E2="Conservar URL","200 · misma URL","301"),"404")) -> 200 · sin cambio
A3: https://www.continentalmedia.com.mx/404-page/ | B3: /404-page/ | C3: Páginas | E3: 404 | F3: — | J3: =IF(E3="301",301,IF(E3="404",404,200)) -> 404 | K3: =IF($E3="404","",IF($F3="ARTICULO",IF($I3<=Destinos!$B$5,"[artículo "&$G3&"] /blog/<slug>/",IFERROR(INDEX(Destinos!$H$9:$H$25,MATCH($H3,Destinos!$E$9:$E$25,0)),Destinos!$C$15)),INDEX(Destinos!$H$9:$H$25,MATCH($F3,Destinos!$A$9:$A$25,0)))) | L3: =IF($K3="","",IF(LEFT($K3,1)="/",Destinos!$B$4&$K3,$K3)) | M3: =IF($E3="404","",IF($F3="ARTICULO","Artículo "&$G3&" → /blog/<slug>/",INDEX(Destinos!$C$9:$C$25,MATCH($F3,Destinos!$A$9:$A$25,0)))) | N3: =IF(AND($E3="301",$F3="ARTICULO"),$I3,"") | O3: R-PAG-03 | P3: Página técnica/de prueba | S3: =IF(AND($E3="404",OR(N($Q3)>0,N($R3)>0)),"REVISAR: tiene clics o enlaces → pasar a 301","") | T3: =IF(OR($E3="Conservar URL",AND($E3="301",OR(N($Q3)>=2,$C3="Páginas"))),"Sí","No") -> No | U3: =IF($E3="Sin cambio","200 · sin cambio",IF($T3="Sí",IF($E3="Conservar URL","200 · misma URL","301"),"404")) -> 404
A4: https://www.continentalmedia.com.mx/agencia-de-publicidad/ | B4: /agencia-de-publicidad/ | C4: Páginas | E4: 301 | F4: HOME | J4: =IF(E4="301",301,IF(E4="404",404,200)) -> 301 | K4: =IF($E4="404","",IF($F4="ARTICULO",IF($I4<=Destinos!$B$5,"[artículo "&$G4&"] /blog/<slug>/",IFERROR(INDEX(Destinos!$H$9:$H$25,MATCH($H4,Destinos!$E$9:$E$25,0)),Destinos!$C$15)),INDEX(Destinos!$H$9:$H$25,MATCH($F4,Destinos!$A$9:$A$25,0)))) -> / | L4: =IF($K4="","",IF(LEFT($K4,1)="/",Destinos!$B$4&$K4,$K4)) -> https://continentalmedia.com.mx/ | M4: =IF($E4="404","",IF($F4="ARTICULO","Artículo "&$G4&" → /blog/<slug>/",INDEX(Destinos!$C$9:$C$25,MATCH($F4,Destinos!$A$9:$A$25,0)))) -> / | N4: =IF(AND($E4="301",$F4="ARTICULO"),$I4,"") | O4: R-PAG-04 | P4: Landing con la keyword «agencia de publicidad»: reflejarla en title/H1 del home nuevo | Q4: 5 | S4: =IF(AND($E4="404",OR(N($Q4)>0,N($R4)>0)),"REVISAR: tiene clics o enlaces → pasar a 301","") | T4: =IF(OR($E4="Conservar URL",AND($E4="301",OR(N($Q4)>=2,$C4="Páginas"))),"Sí","No") -> Sí | U4: =IF($E4="Sin cambio","200 · sin cambio",IF($T4="Sí",IF($E4="Conservar URL","200 · misma URL","301"),"404")) -> 301
A5: https://www.continentalmedia.com.mx/contacto/ | B5: /contacto/ | C5: Páginas | E5: 301 | F5: CONTACTO | J5: =IF(E5="301",301,IF(E5="404",404,200)) -> 301 | K5: =IF($E5="404","",IF($F5="ARTICULO",IF($I5<=Destinos!$B$5,"[artículo "&$G5&"] /blog/<slug>/",IFERROR(INDEX(Destinos!$H$9:$H$25,MATCH($H5,Destinos!$E$9:$E$25,0)),Destinos!$C$15)),INDEX(Destinos!$H$9:$H$25,MATCH($F5,Destinos!$A$9:$A$25,0)))) -> /#contacto | L5: =IF($K5="","",IF(LEFT($K5,1)="/",Destinos!$B$4&$K5,$K5)) -> https://continentalmedia.com.mx/#contacto | M5: =IF($E5="404","",IF($F5="ARTICULO","Artículo "&$G5&" → /blog/<slug>/",INDEX(Destinos!$C$9:$C$25,MATCH($F5,Destinos!$A$9:$A$25,0)))) -> /#contacto | N5: =IF(AND($E5="301",$F5="ARTICULO"),$I5,"") | O5: R-PAG-02 | Q5: 16 | S5: =IF(AND($E5="404",OR(N($Q5)>0,N($R5)>0)),"REVISAR: tiene clics o enlaces → pasar a 301","") | T5: =IF(OR($E5="Conservar URL",AND($E5="301",OR(N($Q5)>=2,$C5="Páginas"))),"Sí","No") -> Sí | U5: =IF($E5="Sin cambio","200 · sin cambio",IF($T5="Sí",IF($E5="Conservar URL","200 · misma URL","301"),"404")) -> 301
A6: https://www.continentalmedia.com.mx/elementor-3504/ | B6: /elementor-3504/ | C6: Páginas | E6: 404 | F6: — | J6: =IF(E6="301",301,IF(E6="404",404,200)) -> 404 | K6: =IF($E6="404","",IF($F6="ARTICULO",IF($I6<=Destinos!$B$5,"[artículo "&$G6&"] /blog/<slug>/",IFERROR(INDEX(Destinos!$H$9:$H$25,MATCH($H6,Destinos!$E$9:$E$25,0)),Destinos!$C$15)),INDEX(Destinos!$H$9:$H$25,MATCH($F6,Destinos!$A$9:$A$25,0)))) | L6: =IF($K6="","",IF(LEFT($K6,1)="/",Destinos!$B$4&$K6,$K6)) | M6: =IF($E6="404","",IF($F6="ARTICULO","Artículo "&$G6&" → /blog/<slug>/",INDEX(Destinos!$C$9:$C$25,MATCH($F6,Destinos!$A$9:$A$25,0)))) | N6: =IF(AND($E6="301",$F6="ARTICULO"),$I6,"") | O6: R-PAG-03 | P6: Página técnica/de prueba | S6: =IF(AND($E6="404",OR(N($Q6)>0,N($R6)>0)),"REVISAR: tiene clics o enlaces → pasar a 301","") | T6: =IF(OR($E6="Conservar URL",AND($E6="301",OR(N($Q6)>=2,$C6="Páginas"))),"Sí","No") -> No | U6: =IF($E6="Sin cambio","200 · sin cambio",IF($T6="Sí",IF($E6="Conservar URL","200 · misma URL","301"),"404")) -> 404
A7: https://www.continentalmedia.com.mx/homepage-revolution/ | B7: /homepage-revolution/ | C7: Páginas | E7: 404 | F7: — | J7: =IF(E7="301",301,IF(E7="404",404,200)) -> 404 | K7: =IF($E7="404","",IF($F7="ARTICULO",IF($I7<=Destinos!$B$5,"[artículo "&$G7&"] /blog/<slug>/",IFERROR(INDEX(Destinos!$H$9:$H$25,MATCH($H7,Destinos!$E$9:$E$25,0)),Destinos!$C$15)),INDEX(Destinos!$H$9:$H$25,MATCH($F7,Destinos!$A$9:$A$25,0)))) | L7: =IF($K7="","",IF(LEFT($K7,1)="/",Destinos!$B$4&$K7,$K7)) | M7: =IF($E7="404","",IF($F7="ARTICULO","Artículo "&$G7&" → /blog/<slug>/",INDEX(Destinos!$C$9:$C$25,MATCH($F7,Destinos!$A$9:$A$25,0)))) | N7: =IF(AND($E7="301",$F7="ARTICULO"),$I7,"") | O7: R-PAG-03 | P7: Página técnica/de prueba | Q7: 1 | S7: =IF(AND($E7="404",OR(N($Q7)>0,N($R7)>0)),"REVISAR: tiene clics o enlaces → pasar a 301","") -> REVISAR: tiene clics o enlaces → pasar a 301 | T7: =IF(OR($E7="Conservar URL",AND($E7="301",OR(N($Q7)>=2,$C7="Páginas"))),"Sí","No") -> No | U7: =IF($E7="Sin cambio","200 · sin cambio",IF($T7="Sí",IF($E7="Conservar URL","200 · misma URL","301"),"404")) -> 404
A8: https://www.continentalmedia.com.mx/nuestros-servicios/ | B8: /nuestros-servicios/ | C8: Páginas | E8: 301 | F8: SERVICIOS | J8: =IF(E8="301",301,IF(E8="404",404,200)) -> 301 | K8: =IF($E8="404","",IF($F8="ARTICULO",IF($I8<=Destinos!$B$5,"[artículo "&$G8&"] /blog/<slug>/",IFERROR(INDEX(Destinos!$H$9:$H$25,MATCH($H8,Destinos!$E$9:$E$25,0)),Destinos!$C$15)),INDEX(Destinos!$H$9:$H$25,MATCH($F8,Destinos!$A$9:$A$25,0)))) -> /#servicios | L8: =IF($K8="","",IF(LEFT($K8,1)="/",Destinos!$B$4&$K8,$K8)) -> https://continentalmedia.com.mx/#servicios | M8: =IF($E8="404","",IF($F8="ARTICULO","Artículo "&$G8&" → /blog/<slug>/",INDEX(Destinos!$C$9:$C$25,MATCH($F8,Destinos!$A$9:$A$25,0)))) -> /#servicios | N8: =IF(AND($E8="301",$F8="ARTICULO"),$I8,"") | O8: R-PAG-02 | Q8: 2 | S8: =IF(AND($E8="404",OR(N($Q8)>0,N($R8)>0)),"REVISAR: tiene clics o enlaces → pasar a 301","") | T8: =IF(OR($E8="Conservar URL",AND($E8="301",OR(N($Q8)>=2,$C8="Páginas"))),"Sí","No") -> Sí | U8: =IF($E8="Sin cambio","200 · sin cambio",IF($T8="Sí",IF($E8="Conservar URL","200 · misma URL","301"),"404")) -> 301
A9: https://www.continentalmedia.com.mx/pagina-inicial/ | B9: /pagina-inicial/ | C9: Páginas | E9: 404 | F9: — | J9: =IF(E9="301",301,IF(E9="404",404,200)) -> 404 | K9: =IF($E9="404","",IF($F9="ARTICULO",IF($I9<=Destinos!$B$5,"[artículo "&$G9&"] /blog/<slug>/",IFERROR(INDEX(Destinos!$H$9:$H$25,MATCH($H9,Destinos!$E$9:$E$25,0)),Destinos!$C$15)),INDEX(Destinos!$H$9:$H$25,MATCH($F9,Destinos!$A$9:$A$25,0)))) | L9: =IF($K9="","",IF(LEFT($K9,1)="/",Destinos!$B$4&$K9,$K9)) | M9: =IF($E9="404","",IF($F9="ARTICULO","Artículo "&$G9&" → /blog/<slug>/",INDEX(Destinos!$C$9:$C$25,MATCH($F9,Destinos!$A$9:$A$25,0)))) | N9: =IF(AND($E9="301",$F9="ARTICULO"),$I9,"") | O9: R-PAG-03 | P9: Página técnica/de prueba | Q9: 1 | S9: =IF(AND($E9="404",OR(N($Q9)>0,N($R9)>0)),"REVISAR: tiene clics o enlaces → pasar a 301","") -> REVISAR: tiene clics o enlaces → pasar a 301 | T9: =IF(OR($E9="Conservar URL",AND($E9="301",OR(N($Q9)>=2,$C9="Páginas"))),"Sí","No") -> No | U9: =IF($E9="Sin cambio","200 · sin cambio",IF($T9="Sí",IF($E9="Conservar URL","200 · misma URL","301"),"404")) -> 404
A10: https://www.continentalmedia.com.mx/portafolio/ | B10: /portafolio/ | C10: Páginas | E10: 301 | F10: PROYECTOS | J10: =IF(E10="301",301,IF(E10="404",404,200)) -> 301 | K10: =IF($E10="404","",IF($F10="ARTICULO",IF($I10<=Destinos!$B$5,"[artículo "&$G10&"] /blog/<slug>/",IFERROR(INDEX(Destinos!$H$9:$H$25,MATCH($H10,Destinos!$E$9:$E$25,0)),Destinos!$C$15)),INDEX(Destinos!$H$9:$H$25,MATCH($F10,Destinos!$A$9:$A$25,0)))) -> /proyectos/ | L10: =IF($K10="","",IF(LEFT($K10,1)="/",Destinos!$B$4&$K10,$K10)) -> https://continentalmedia.com.mx/proyectos/ | M10: =IF($E10="404","",IF($F10="ARTICULO","Artículo "&$G10&" → /blog/<slug>/",INDEX(Destinos!$C$9:$C$25,MATCH($F10,Destinos!$A$9:$A$25,0)))) -> /proyectos/ | N10: =IF(AND($E10="301",$F10="ARTICULO"),$I10,"") | O10: R-PAG-02 | Q10: 3 | S10: =IF(AND($E10="404",OR(N($Q10)>0,N($R10)>0)),"REVISAR: tiene clics o enlaces → pasar a 301","") | T10: =IF(OR($E10="Conservar URL",AND($E10="301",OR(N($Q10)>=2,$C10="Páginas"))),"Sí","No") -> Sí | U10: =IF($E10="Sin cambio","200 · sin cambio",IF($T10="Sí",IF($E10="Conservar URL","200 · misma URL","301"),"404")) -> 301
A11: https://www.continentalmedia.com.mx/testing-1/ | B11: /testing-1/ | C11: Páginas | E11: 404 | F11: — | J11: =IF(E11="301",301,IF(E11="404",404,200)) -> 404 | K11: =IF($E11="404","",IF($F11="ARTICULO",IF($I11<=Destinos!$B$5,"[artículo "&$G11&"] /blog/<slug>/",IFERROR(INDEX(Destinos!$H$9:$H$25,MATCH($H11,Destinos!$E$9:$E$25,0)),Destinos!$C$15)),INDEX(Destinos!$H$9:$H$25,MATCH($F11,Destinos!$A$9:$A$25,0)))) | L11: =IF($K11="","",IF(LEFT($K11,1)="/",Destinos!$B$4&$K11,$K11)) | M11: =IF($E11="404","",IF($F11="ARTICULO","Artículo "&$G11&" → /blog/<slug>/",INDEX(Destinos!$C$9:$C$25,MATCH($F11,Destinos!$A$9:$A$25,0)))) | N11: =IF(AND($E11="301",$F11="ARTICULO"),$I11,"") | O11: R-PAG-03 | P11: Página técnica/de prueba | S11: =IF(AND($E11="404",OR(N($Q11)>0,N($R11)>0)),"REVISAR: tiene clics o enlaces → pasar a 301","") | T11: =IF(OR($E11="Conservar URL",AND($E11="301",OR(N($Q11)>=2,$C11="Páginas"))),"Sí","No") -> No | U11: =IF($E11="Sin cambio","200 · sin cambio",IF($T11="Sí",IF($E11="Conservar URL","200 · misma URL","301"),"404")) -> 404
A12: https://www.continentalmedia.com.mx/usa/ | B12: /usa/ | C12: Páginas | E12: 301 | F12: HOME | J12: =IF(E12="301",301,IF(E12="404",404,200)) -> 301 | K12: =IF($E12="404","",IF($F12="ARTICULO",IF($I12<=Destinos!$B$5,"[artículo "&$G12&"] /blog/<slug>/",IFERROR(INDEX(Destinos!$H$9:$H$25,MATCH($H12,Destinos!$E$9:$E$25,0)),Destinos!$C$15)),INDEX(Destinos!$H$9:$H$25,MATCH($F12,Destinos!$A$9:$A$25,0)))) -> / | L12: =IF($K12="","",IF(LEFT($K12,1)="/",Destinos!$B$4&$K12,$K12)) -> https://continentalmedia.com.mx/ | M12: =IF($E12="404","",IF($F12="ARTICULO","Artículo "&$G12&" → /blog/<slug>/",INDEX(Destinos!$C$9:$C$25,MATCH($F12,Destinos!$A$9:$A$25,0)))) -> / | N12: =IF(AND($E12="301",$F12="ARTICULO"),$I12,"") | O12: R-PAG-04 | P12: Revisar contenido original (HTTP 500 en la revisión). Candidata a tema E-47 (consumidor hispano en EE.UU.) cuando se publique | Q12: 5 | S12: =IF(AND($E12="404",OR(N($Q12)>0,N($R12)>0)),"REVISAR: tiene clics o enlaces → pasar a 301","") | T12: =IF(OR($E12="Conservar URL",AND($E12="301",OR(N($Q12)>=2,$C12="Páginas"))),"Sí","No") -> Sí | U12: =IF($E12="Sin cambio","200 · sin cambio",IF($T12="Sí",IF($E12="Conservar URL","200 · misma URL","301"),"404")) -> 301
A13: https://www.continentalmedia.com.mx/2012/08/creative-interior-design/ | B13: /2012/08/creative-interior-design/ | C13: Blog | E13: 404 | F13: — | J13: =IF(E13="301",301,IF(E13="404",404,200)) -> 404 | K13: =IF($E13="404","",IF($F13="ARTICULO",IF($I13<=Destinos!$B$5,"[artículo "&$G13&"] /blog/<slug>/",IFERROR(INDEX(Destinos!$H$9:$H$25,MATCH($H13,Destinos!$E$9:$E$25,0)),Destinos!$C$15)),INDEX(Destinos!$H$9:$H$25,MATCH($F13,Destinos!$A$9:$A$25,0)))) | L13: =IF($K13="","",IF(LEFT($K13,1)="/",Destinos!$B$4&$K13,$K13)) | M13: =IF($E13="404","",IF($F13="ARTICULO","Artículo "&$G13&" → /blog/<slug>/",INDEX(Destinos!$C$9:$C$25,MATCH($F13,Destinos!$A$9:$A$25,0)))) | N13: =IF(AND($E13="301",$F13="ARTICULO"),$I13,"") | O13: R-BLOG-02 | P13: Sin valor SEO actual; sin tema equivalente | S13: =IF(AND($E13="404",OR(N($Q13)>0,N($R13)>0)),"REVISAR: tiene clics o enlaces → pasar a 301","") | T13: =IF(OR($E13="Conservar URL",AND($E13="301",OR(N($Q13)>=2,$C13="Páginas"))),"Sí","No") -> No | U13: =IF($E13="Sin cambio","200 · sin cambio",IF($T13="Sí",IF($E13="Conservar URL","200 · misma URL","301"),"404")) -> 404
A14: https://www.continentalmedia.com.mx/2012/08/marketing-olfativo/ | B14: /2012/08/marketing-olfativo/ | C14: Blog | E14: 301 | F14: ARTICULO | G14: E-20 | H14: Branding, diseño y creatividad | I14: 46427 | J14: =IF(E14="301",301,IF(E14="404",404,200)) -> 301 | K14: =IF($E14="404","",IF($F14="ARTICULO",IF($I14<=Destinos!$B$5,"[artículo "&$G14&"] /blog/<slug>/",IFERROR(INDEX(Destinos!$H$9:$H$25,MATCH($H14,Destinos!$E$9:$E$25,0)),Destinos!$C$15)),INDEX(Destinos!$H$9:$H$25,MATCH($F14,Destinos!$A$9:$A$25,0)))) -> /blog/ | L14: =IF($K14="","",IF(LEFT($K14,1)="/",Destinos!$B$4&$K14,$K14)) -> https://continentalmedia.com.mx/blog/ | M14: =IF($E14="404","",IF($F14="ARTICULO","Artículo "&$G14&" → /blog/<slug>/",INDEX(Destinos!$C$9:$C$25,MATCH($F14,Destinos!$A$9:$A$25,0)))) -> Artículo E-20 → /blog/<slug>/ | N14: =IF(AND($E14="301",$F14="ARTICULO"),$I14,"") -> 46427 | O14: R-BLOG-01 | S14: =IF(AND($E14="404",OR(N($Q14)>0,N($R14)>0)),"REVISAR: tiene clics o enlaces → pasar a 301","") | T14: =IF(OR($E14="Conservar URL",AND($E14="301",OR(N($Q14)>=2,$C14="Páginas"))),"Sí","No") -> No | U14: =IF($E14="Sin cambio","200 · sin cambio",IF($T14="Sí",IF($E14="Conservar URL","200 · misma URL","301"),"404")) -> 404
A15: https://www.continentalmedia.com.mx/2012/12/6-razones-pymes-usar-redes-sociales/ | B15: /2012/12/6-razones-pymes-usar-redes-sociales/ | C15: Blog | E15: 301 | F15: ARTICULO | G15: E-10 | H15: Redes sociales y comunidad | I15: 46378 | J15: =IF(E15="301",301,IF(E15="404",404,200)) -> 301 | K15: =IF($E15="404","",IF($F15="ARTICULO",IF($I15<=Destinos!$B$5,"[artículo "&$G15&"] /blog/<slug>/",IFERROR(INDEX(Destinos!$H$9:$H$25,MATCH($H15,Destinos!$E$9:$E$25,0)),Destinos!$C$15)),INDEX(Destinos!$H$9:$H$25,MATCH($F15,Destinos!$A$9:$A$25,0)))) -> /blog/categoria/redes-sociales/ | L15: =IF($K15="","",IF(LEFT($K15,1)="/",Destinos!$B$4&$K15,$K15)) -> https://continentalmedia.com.mx/blog/categoria/redes-sociales/ | M15: =IF($E15="404","",IF($F15="ARTICULO","Artículo "&$G15&" → /blog/<slug>/",INDEX(Destinos!$C$9:$C$25,MATCH($F15,Destinos!$A$9:$A$25,0)))) -> Artículo E-10 → /blog/<slug>/ | N15: =IF(AND($E15="301",$F15="ARTICULO"),$I15,"") -> 46378 | O15: R-BLOG-01 | S15: =IF(AND($E15="404",OR(N($Q15)>0,N($R15)>0)),"REVISAR: tiene clics o enlaces → pasar a 301","") | T15: =IF(OR($E15="Conservar URL",AND($E15="301",OR(N($Q15)>=2,$C15="Páginas"))),"Sí","No") -> No | U15: =IF($E15="Sin cambio","200 · sin cambio",IF($T15="Sí",IF($E15="Conservar URL","200 · misma URL","301"),"404")) -> 404
A16: https://www.continentalmedia.com.mx/2012/12/campanas-exitosas-del-2012/ | B16: /2012/12/campanas-exitosas-del-2012/ | C16: Blog | E16: 301 | F16: BLOG | J16: =IF(E16="301",301,IF(E16="404",404,200)) -> 301 | K16: =IF($E16="404","",IF($F16="ARTICULO",IF($I16<=Destinos!$B$5,"[artículo "&$G16&"] /blog/<slug>/",IFERROR(INDEX(Destinos!$H$9:$H$25,MATCH($H16,Destinos!$E$9:$E$25,0)),Destinos!$C$15)),INDEX(Destinos!$H$9:$H$25,MATCH($F16,Destinos!$A$9:$A$25,0)))) -> /blog/ | L16: =IF($K16="","",IF(LEFT($K16,1)="/",Destinos!$B$4&$K16,$K16)) -> https://continentalmedia.com.mx/blog/ | M16: =IF($E16="404","",IF($F16="ARTICULO","Artículo "&$G16&" → /blog/<slug>/",INDEX(Destinos!$C$9:$C$25,MATCH($F16,Destinos!$A$9:$A$25,0)))) -> /blog/ | N16: =IF(AND($E16="301",$F16="ARTICULO"),$I16,"") | O16: R-LISTA-02 | P16: Descartado en el backlog pero con clics (2 a 7 en 16 meses); decisión: 301 al índice del blog. | Q16: 7 | S16: =IF(AND($E16="404",OR(N($Q16)>0,N($R16)>0)),"REVISAR: tiene clics o enlaces → pasar a 301","") | T16: =IF(OR($E16="Conservar URL",AND($E16="301",OR(N($Q16)>=2,$C16="Páginas"))),"Sí","No") -> Sí | U16: =IF($E16="Sin cambio","200 · sin cambio",IF($T16="Sí",IF($E16="Conservar URL","200 · misma URL","301"),"404")) -> 301
A17: https://www.continentalmedia.com.mx/2012/12/churros-creatividad/ | B17: /2012/12/churros-creatividad/ | C17: Blog | E17: 301 | F17: ARTICULO | G17: E-33 | H17: Branding, diseño y creatividad | I17: 46504 | J17: =IF(E17="301",301,IF(E17="404",404,200)) -> 301 | K17: =IF($E17="404","",IF($F17="ARTICULO",IF($I17<=Destinos!$B$5,"[artículo "&$G17&"] /blog/<slug>/",IFERROR(INDEX(Destinos!$H$9:$H$25,MATCH($H17,Destinos!$E$9:$E$25,0)),Destinos!$C$15)),INDEX(Destinos!$H$9:$H$25,MATCH($F17,Destinos!$A$9:$A$25,0)))) -> /blog/ | L17: =IF($K17="","",IF(LEFT($K17,1)="/",Destinos!$B$4&$K17,$K17)) -> https://continentalmedia.com.mx/blog/ | M17: =IF($E17="404","",IF($F17="ARTICULO","Artículo "&$G17&" → /blog/<slug>/",INDEX(Destinos!$C$9:$C$25,MATCH($F17,Destinos!$A$9:$A$25,0)))) -> Artículo E-33 → /blog/<slug>/ | N17: =IF(AND($E17="301",$F17="ARTICULO"),$I17,"") -> 46504 | O17: R-BLOG-01 | S17: =IF(AND($E17="404",OR(N($Q17)>0,N($R17)>0)),"REVISAR: tiene clics o enlaces → pasar a 301","") | T17: =IF(OR($E17="Conservar URL",AND($E17="301",OR(N($Q17)>=2,$C17="Páginas"))),"Sí","No") -> No | U17: =IF($E17="Sin cambio","200 · sin cambio",IF($T17="Sí",IF($E17="Conservar URL","200 · misma URL","301"),"404")) -> 404
A18: https://www.continentalmedia.com.mx/2012/12/conoce-el-funcionamiento-del-e-mail-marketing/ | B18: /2012/12/conoce-el-funcionamiento-del-e-mail-marketing/ | C18: Blog | E18: 301 | F18: ARTICULO | G18: G-42 | H18: Web, SEO y publicidad digital | I18: 46569 | J18: =IF(E18="301",301,IF(E18="404",404,200)) -> 301 | K18: =IF($E18="404","",IF($F18="ARTICULO",IF($I18<=Destinos!$B$5,"[artículo "&$G18&"] /blog/<slug>/",IFERROR(INDEX(Destinos!$H$9:$H$25,MATCH($H18,Destinos!$E$9:$E$25,0)),Destinos!$C$15)),INDEX(Destinos!$H$9:$H$25,MATCH($F18,Destinos!$A$9:$A$25,0)))) -> /blog/ | L18: =IF($K18="","",IF(LEFT($K18,1)="/",Destinos!$B$4&$K18,$K18)) -> https://continentalmedia.com.mx/blog/ | M18: =IF($E18="404","",IF($F18="ARTICULO","Artículo "&$G18&" → /blog/<slug>/",INDEX(Destinos!$C$9:$C$25,MATCH($F18,Destinos!$A$9:$A$25,0)))) -> Artículo G-42 → /blog/<slug>/ | N18: =IF(AND($E18="301",$F18="ARTICULO"),$I18,"") -> 46569 | O18: R-BLOG-01 | S18: =IF(AND($E18="404",OR(N($Q18)>0,N($R18)>0)),"REVISAR: tiene clics o enlaces → pasar a 301","") | T18: =IF(OR($E18="Conservar URL",AND($E18="301",OR(N($Q18)>=2,$C18="Páginas"))),"Sí","No") -> No | U18: =IF($E18="Sin cambio","200 · sin cambio",IF($T18="Sí",IF($E18="Conservar URL","200 · misma URL","301"),"404")) -> 404
A19: https://www.continentalmedia.com.mx/2012/12/es-necesario-ofrecer-una-buena-atencion-al-cliente-en-las-redes-sociales/ | B19: /2012/12/es-necesario-ofrecer-una-buena-atencion-al-cliente-en-las-redes-sociales/ | C19: Blog | E19: 301 | F19: ARTICULO | G19: G-14 | H19: Redes sociales y comunidad | I19: 46499 | J19: =IF(E19="301",301,IF(E19="404",404,200)) -> 301 | K19: =IF($E19="404","",IF($F19="ARTICULO",IF($I19<=Destinos!$B$5,"[artículo "&$G19&"] /blog/<slug>/",IFERROR(INDEX(Destinos!$H$9:$H$25,MATCH($H19,Destinos!$E$9:$E$25,0)),Destinos!$C$15)),INDEX(Destinos!$H$9:$H$25,MATCH($F19,Destinos!$A$9:$A$25,0)))) -> /blog/categoria/redes-sociales/ | L19: =IF($K19="","",IF(LEFT($K19,1)="/",Destinos!$B$4&$K19,$K19)) -> https://continentalmedia.com.mx/blog/categoria/redes-sociales/ | M19: =IF($E19="404","",IF($F19="ARTICULO","Artículo "&$G19&" → /blog/<slug>/",INDEX(Destinos!$C$9:$C$25,MATCH($F19,Destinos!$A$9:$A$25,0)))) -> Artículo G-14 → /blog/<slug>/ | N19: =IF(AND($E19="301",$F19="ARTICULO"),$I19,"") -> 46499 | O19: R-BLOG-01 | S19: =IF(AND($E19="404",OR(N($Q19)>0,N($R19)>0)),"REVISAR: tiene clics o enlaces → pasar a 301","") | T19: =IF(OR($E19="Conservar URL",AND($E19="301",OR(N($Q19)>=2,$C19="Páginas"))),"Sí","No") -> No | U19: =IF($E19="Sin cambio","200 · sin cambio",IF($T19="Sí",IF($E19="Conservar URL","200 · misma URL","301"),"404")) -> 404
A20: https://www.continentalmedia.com.mx/2012/12/inversion-publicitaria-en-medios-online/ | B20: /2012/12/inversion-publicitaria-en-medios-online/ | C20: Blog | E20: 301 | F20: ARTICULO | G20: E-45 | H20: Eventos, medios y publicidad exterior | I20: 46616 | J20: =IF(E20="301",301,IF(E20="404",404,200)) -> 301 | K20: =IF($E20="404","",IF($F20="ARTICULO",IF($I20<=Destinos!$B$5,"[artículo "&$G20&"] /blog/<slug>/",IFERROR(INDEX(Destinos!$H$9:$H$25,MATCH($H20,Destinos!$E$9:$E$25,0)),Destinos!$C$15)),INDEX(Destinos!$H$9:$H$25,MATCH($F20,Destinos!$A$9:$A$25,0)))) -> /blog/ | L20: =IF($K20="","",IF(LEFT($K20,1)="/",Destinos!$B$4&$K20,$K20)) -> https://continentalmedia.com.mx/blog/ | M20: =IF($E20="404","",IF($F20="ARTICULO","Artículo "&$G20&" → /blog/<slug>/",INDEX(Destinos!$C$9:$C$25,MATCH($F20,Destinos!$A$9:$A$25,0)))) -> Artículo E-45 → /blog/<slug>/ | N20: =IF(AND($E20="301",$F20="ARTICULO"),$I20,"") -> 46616 | O20: R-BLOG-01 | S20: =IF(AND($E20="404",OR(N($Q20)>0,N($R20)>0)),"REVISAR: tiene clics o enlaces → pasar a 301","") | T20: =IF(OR($E20="Conservar URL",AND($E20="301",OR(N($Q20)>=2,$C20="Páginas"))),"Sí","No") -> No | U20: =IF($E20="Sin cambio","200 · sin cambio",IF($T20="Sí",IF($E20="Conservar URL","200 · misma URL","301"),"404")) -> 404
A21: https://www.continentalmedia.com.mx/2012/12/las-4-r-s-de-las-redes-sociales/ | B21: /2012/12/las-4-r-s-de-las-redes-sociales/ | C21: Blog | E21: 301 | F21: ARTICULO | G21: E-15 | H21: Redes sociales y comunidad | I21: 46399 | J21: =IF(E21="301",301,IF(E21="404",404,200)) -> 301 | K21: =IF($E21="404","",IF($F21="ARTICULO",IF($I21<=Destinos!$B$5,"[artículo "&$G21&"] /blog/<slug>/",IFERROR(INDEX(Destinos!$H$9:$H$25,MATCH($H21,Destinos!$E$9:$E$25,0)),Destinos!$C$15)),INDEX(Destinos!$H$9:$H$25,MATCH($F21,Destinos!$A$9:$A$25,0)))) -> /blog/categoria/redes-sociales/ | L21: =IF($K21="","",IF(LEFT($K21,1)="/",Destinos!$B$4&$K21,$K21)) -> https://continentalmedia.com.mx/blog/categoria/redes-sociales/ | M21: =IF($E21="404","",IF($F21="ARTICULO","Artículo "&$G21&" → /blog/<slug>/",INDEX(Destinos!$C$9:$C$25,MATCH($F21,Destinos!$A$9:$A$25,0)))) -> Artículo E-15 → /blog/<slug>/ | N21: =IF(AND($E21="301",$F21="ARTICULO"),$I21,"") -> 46399 | O21: R-BLOG-01 | S21: =IF(AND($E21="404",OR(N($Q21)>0,N($R21)>0)),"REVISAR: tiene clics o enlaces → pasar a 301","") | T21: =IF(OR($E21="Conservar URL",AND($E21="301",OR(N($Q21)>=2,$C21="Páginas"))),"Sí","No") -> No | U21: =IF($E21="Sin cambio","200 · sin cambio",IF($T21="Sí",IF($E21="Conservar URL","200 · misma URL","301"),"404")) -> 404
A22: https://www.continentalmedia.com.mx/2012/12/lovemarks/ | B22: /2012/12/lovemarks/ | C22: Blog | E22: 301 | F22: ARTICULO | G22: E-26 | H22: Branding, diseño y creatividad | I22: 46574 | J22: =IF(E22="301",301,IF(E22="404",404,200)) -> 301 | K22: =IF($E22="404","",IF($F22="ARTICULO",IF($I22<=Destinos!$B$5,"[artículo "&$G22&"] /blog/<slug>/",IFERROR(INDEX(Destinos!$H$9:$H$25,MATCH($H22,Destinos!$E$9:$E$25,0)),Destinos!$C$15)),INDEX(Destinos!$H$9:$H$25,MATCH($F22,Destinos!$A$9:$A$25,0)))) -> /blog/ | L22: =IF($K22="","",IF(LEFT($K22,1)="/",Destinos!$B$4&$K22,$K22)) -> https://continentalmedia.com.mx/blog/ | M22: =IF($E22="404","",IF($F22="ARTICULO","Artículo "&$G22&" → /blog/<slug>/",INDEX(Destinos!$C$9:$C$25,MATCH($F22,Destinos!$A$9:$A$25,0)))) -> Artículo E-26 → /blog/<slug>/ | N22: =IF(AND($E22="301",$F22="ARTICULO"),$I22,"") -> 46574 | O22: R-BLOG-01 | S22: =IF(AND($E22="404",OR(N($Q22)>0,N($R22)>0)),"REVISAR: tiene clics o enlaces → pasar a 301","") | T22: =IF(OR($E22="Conservar URL",AND($E22="301",OR(N($Q22)>=2,$C22="Páginas"))),"Sí","No") -> No | U22: =IF($E22="Sin cambio","200 · sin cambio",IF($T22="Sí",IF($E22="Conservar URL","200 · misma URL","301"),"404")) -> 404
A23: https://www.continentalmedia.com.mx/2012/12/marketing-de-guerrilla/ | B23: /2012/12/marketing-de-guerrilla/ | C23: Blog | E23: 301 | F23: ARTICULO | G23: E-44 | H23: Eventos, medios y publicidad exterior | I23: 46609 | J23: =IF(E23="301",301,IF(E23="404",404,200)) -> 301 | K23: =IF($E23="404","",IF($F23="ARTICULO",IF($I23<=Destinos!$B$5,"[artículo "&$G23&"] /blog/<slug>/",IFERROR(INDEX(Destinos!$H$9:$H$25,MATCH($H23,Destinos!$E$9:$E$25,0)),Destinos!$C$15)),INDEX(Destinos!$H$9:$H$25,MATCH($F23,Destinos!$A$9:$A$25,0)))) -> /blog/ | L23: =IF($K23="","",IF(LEFT($K23,1)="/",Destinos!$B$4&$K23,$K23)) -> https://continentalmedia.com.mx/blog/ | M23: =IF($E23="404","",IF($F23="ARTICULO","Artículo "&$G23&" → /blog/<slug>/",INDEX(Destinos!$C$9:$C$25,MATCH($F23,Destinos!$A$9:$A$25,0)))) -> Artículo E-44 → /blog/<slug>/ | N23: =IF(AND($E23="301",$F23="ARTICULO"),$I23,"") -> 46609 | O23: R-BLOG-01 | S23: =IF(AND($E23="404",OR(N($Q23)>0,N($R23)>0)),"REVISAR: tiene clics o enlaces → pasar a 301","") | T23: =IF(OR($E23="Conservar URL",AND($E23="301",OR(N($Q23)>=2,$C23="Páginas"))),"Sí","No") -> No | U23: =IF($E23="Sin cambio","200 · sin cambio",IF($T23="Sí",IF($E23="Conservar URL","200 · misma URL","301"),"404")) -> 404
A24: https://www.continentalmedia.com.mx/2012/12/marketing-deportivo/ | B24: /2012/12/marketing-deportivo/ | C24: Blog | E24: 301 | F24: ARTICULO | G24: E-46 | H24: Eventos, medios y publicidad exterior | I24: 46623 | J24: =IF(E24="301",301,IF(E24="404",404,200)) -> 301 | K24: =IF($E24="404","",IF($F24="ARTICULO",IF($I24<=Destinos!$B$5,"[artículo "&$G24&"] /blog/<slug>/",IFERROR(INDEX(Destinos!$H$9:$H$25,MATCH($H24,Destinos!$E$9:$E$25,0)),Destinos!$C$15)),INDEX(Destinos!$H$9:$H$25,MATCH($F24,Destinos!$A$9:$A$25,0)))) -> /blog/ | L24: =IF($K24="","",IF(LEFT($K24,1)="/",Destinos!$B$4&$K24,$K24)) -> https://continentalmedia.com.mx/blog/ | M24: =IF($E24="404","",IF($F24="ARTICULO","Artículo "&$G24&" → /blog/<slug>/",INDEX(Destinos!$C$9:$C$25,MATCH($F24,Destinos!$A$9:$A$25,0)))) -> Artículo E-46 → /blog/<slug>/ | N24: =IF(AND($E24="301",$F24="ARTICULO"),$I24,"") -> 46623 | O24: R-BLOG-01 | S24: =IF(AND($E24="404",OR(N($Q24)>0,N($R24)>0)),"REVISAR: tiene clics o enlaces → pasar a 301","") | T24: =IF(OR($E24="Conservar URL",AND($E24="301",OR(N($Q24)>=2,$C24="Páginas"))),"Sí","No") -> No | U24: =IF($E24="Sin cambio","200 · sin cambio",IF($T24="Sí",IF($E24="Conservar URL","200 · misma URL","301"),"404")) -> 404
A25: https://www.continentalmedia.com.mx/2012/12/marketing-viral/ | B25: /2012/12/marketing-viral/ | C25: Blog | E25: 301 | F25: ARTICULO | G25: E-15 | H25: Redes sociales y comunidad | I25: 46399 | J25: =IF(E25="301",301,IF(E25="404",404,200)) -> 301 | K25: =IF($E25="404","",IF($F25="ARTICULO",IF($I25<=Destinos!$B$5,"[artículo "&$G25&"] /blog/<slug>/",IFERROR(INDEX(Destinos!$H$9:$H$25,MATCH($H25,Destinos!$E$9:$E$25,0)),Destinos!$C$15)),INDEX(Destinos!$H$9:$H$25,MATCH($F25,Destinos!$A$9:$A$25,0)))) -> /blog/categoria/redes-sociales/ | L25: =IF($K25="","",IF(LEFT($K25,1)="/",Destinos!$B$4&$K25,$K25)) -> https://continentalmedia.com.mx/blog/categoria/redes-sociales/ | M25: =IF($E25="404","",IF($F25="ARTICULO","Artículo "&$G25&" → /blog/<slug>/",INDEX(Destinos!$C$9:$C$25,MATCH($F25,Destinos!$A$9:$A$25,0)))) -> Artículo E-15 → /blog/<slug>/ | N25: =IF(AND($E25="301",$F25="ARTICULO"),$I25,"") -> 46399 | O25: R-BLOG-01 | S25: =IF(AND($E25="404",OR(N($Q25)>0,N($R25)>0)),"REVISAR: tiene clics o enlaces → pasar a 301","") | T25: =IF(OR($E25="Conservar URL",AND($E25="301",OR(N($Q25)>=2,$C25="Páginas"))),"Sí","No") -> No | U25: =IF($E25="Sin cambio","200 · sin cambio",IF($T25="Sí",IF($E25="Conservar URL","200 · misma URL","301"),"404")) -> 404
